Install gpustat with 'pip install gpustat' to enable GPU monitoring.
Traceback (most recent call last):
  File "C:\anaconda3\envs\RLV\lib\site-packages\redis\connection.py", line 1184, in get_connection
    if connection.can_read():
  File "C:\anaconda3\envs\RLV\lib\site-packages\redis\connection.py", line 716, in can_read
    return self._parser.can_read(timeout)
  File "C:\anaconda3\envs\RLV\lib\site-packages\redis\connection.py", line 310, in can_read
    return self._buffer and self._buffer.can_read(timeout)
  File "C:\anaconda3\envs\RLV\lib\site-packages\redis\connection.py", line 220, in can_read
    raise_on_timeout=False)
  File "C:\anaconda3\envs\RLV\lib\site-packages\redis\connection.py", line 190, in _read_from_socket
    raise ConnectionError(SERVER_CLOSED_CONNECTION_ERROR)
redis.exceptions.ConnectionError: Connection closed by server.

During handling of the above exception, another exception occurred:

Traceback (most recent call last):
  File "C:\anaconda3\envs\RLV\lib\site-packages\redis\connection.py", line 550, in connect
    sock = self._connect()
  File "C:\anaconda3\envs\RLV\lib\site-packages\redis\connection.py", line 607, in _connect
    raise err
  File "C:\anaconda3\envs\RLV\lib\site-packages\redis\connection.py", line 595, in _connect
    sock.connect(socket_address)
OSError: [WinError 10065] A socket operation was attempted to an unreachable host

During handling of the above exception, another exception occurred:

Traceback (most recent call last):
  File "C:\anaconda3\envs\RLV\lib\site-packages\ray\reporter.py", line 234, in run
    self.perform_iteration()
  File "C:\anaconda3\envs\RLV\lib\site-packages\ray\reporter.py", line 219, in perform_iteration
    jsonify_asdict(stats),
  File "C:\anaconda3\envs\RLV\lib\site-packages\redis\client.py", line 3052, in publish
    return self.execute_command('PUBLISH', channel, message)
  File "C:\anaconda3\envs\RLV\lib\site-packages\redis\client.py", line 881, in execute_command
    conn = self.connection or pool.get_connection(command_name, **options)
  File "C:\anaconda3\envs\RLV\lib\site-packages\redis\connection.py", line 1188, in get_connection
    connection.connect()
  File "C:\anaconda3\envs\RLV\lib\site-packages\redis\connection.py", line 555, in connect
    raise ConnectionError(self._error_message(e))
redis.exceptions.ConnectionError: Error 10065 connecting to 10.16.234.175:6379. A socket operation was attempted to an unreachable host.
Traceback (most recent call last):
  File "C:\anaconda3\envs\RLV\lib\site-packages\redis\connection.py", line 550, in connect
    sock = self._connect()
  File "C:\anaconda3\envs\RLV\lib\site-packages\redis\connection.py", line 607, in _connect
    raise err
  File "C:\anaconda3\envs\RLV\lib\site-packages\redis\connection.py", line 595, in _connect
    sock.connect(socket_address)
OSError: [WinError 10065] A socket operation was attempted to an unreachable host

During handling of the above exception, another exception occurred:

Traceback (most recent call last):
  File "C:\anaconda3\envs\RLV\lib\site-packages\ray\reporter.py", line 234, in run
    self.perform_iteration()
  File "C:\anaconda3\envs\RLV\lib\site-packages\ray\reporter.py", line 219, in perform_iteration
    jsonify_asdict(stats),
  File "C:\anaconda3\envs\RLV\lib\site-packages\redis\client.py", line 3052, in publish
    return self.execute_command('PUBLISH', channel, message)
  File "C:\anaconda3\envs\RLV\lib\site-packages\redis\client.py", line 881, in execute_command
    conn = self.connection or pool.get_connection(command_name, **options)
  File "C:\anaconda3\envs\RLV\lib\site-packages\redis\connection.py", line 1178, in get_connection
    connection.connect()
  File "C:\anaconda3\envs\RLV\lib\site-packages\redis\connection.py", line 555, in connect
    raise ConnectionError(self._error_message(e))
redis.exceptions.ConnectionError: Error 10065 connecting to 10.16.234.175:6379. A socket operation was attempted to an unreachable host.
Traceback (most recent call last):
  File "C:\anaconda3\envs\RLV\lib\site-packages\redis\connection.py", line 550, in connect
    sock = self._connect()
  File "C:\anaconda3\envs\RLV\lib\site-packages\redis\connection.py", line 607, in _connect
    raise err
  File "C:\anaconda3\envs\RLV\lib\site-packages\redis\connection.py", line 595, in _connect
    sock.connect(socket_address)
OSError: [WinError 10065] A socket operation was attempted to an unreachable host

During handling of the above exception, another exception occurred:

Traceback (most recent call last):
  File "C:\anaconda3\envs\RLV\lib\site-packages\ray\reporter.py", line 234, in run
    self.perform_iteration()
  File "C:\anaconda3\envs\RLV\lib\site-packages\ray\reporter.py", line 219, in perform_iteration
    jsonify_asdict(stats),
  File "C:\anaconda3\envs\RLV\lib\site-packages\redis\client.py", line 3052, in publish
    return self.execute_command('PUBLISH', channel, message)
  File "C:\anaconda3\envs\RLV\lib\site-packages\redis\client.py", line 881, in execute_command
    conn = self.connection or pool.get_connection(command_name, **options)
  File "C:\anaconda3\envs\RLV\lib\site-packages\redis\connection.py", line 1178, in get_connection
    connection.connect()
  File "C:\anaconda3\envs\RLV\lib\site-packages\redis\connection.py", line 555, in connect
    raise ConnectionError(self._error_message(e))
redis.exceptions.ConnectionError: Error 10065 connecting to 10.16.234.175:6379. A socket operation was attempted to an unreachable host.
Traceback (most recent call last):
  File "C:\anaconda3\envs\RLV\lib\site-packages\redis\connection.py", line 550, in connect
    sock = self._connect()
  File "C:\anaconda3\envs\RLV\lib\site-packages\redis\connection.py", line 607, in _connect
    raise err
  File "C:\anaconda3\envs\RLV\lib\site-packages\redis\connection.py", line 595, in _connect
    sock.connect(socket_address)
TimeoutError: [WinError 10060] A connection attempt failed because the connected party did not properly respond after a period of time, or established connection failed because connected host has failed to respond

During handling of the above exception, another exception occurred:

Traceback (most recent call last):
  File "C:\anaconda3\envs\RLV\lib\site-packages\ray\reporter.py", line 234, in run
    self.perform_iteration()
  File "C:\anaconda3\envs\RLV\lib\site-packages\ray\reporter.py", line 219, in perform_iteration
    jsonify_asdict(stats),
  File "C:\anaconda3\envs\RLV\lib\site-packages\redis\client.py", line 3052, in publish
    return self.execute_command('PUBLISH', channel, message)
  File "C:\anaconda3\envs\RLV\lib\site-packages\redis\client.py", line 881, in execute_command
    conn = self.connection or pool.get_connection(command_name, **options)
  File "C:\anaconda3\envs\RLV\lib\site-packages\redis\connection.py", line 1178, in get_connection
    connection.connect()
  File "C:\anaconda3\envs\RLV\lib\site-packages\redis\connection.py", line 555, in connect
    raise ConnectionError(self._error_message(e))
redis.exceptions.ConnectionError: Error 10060 connecting to 10.16.234.175:6379. A connection attempt failed because the connected party did not properly respond after a period of time, or established connection failed because connected host has failed to respond.
Traceback (most recent call last):
  File "C:\anaconda3\envs\RLV\lib\site-packages\redis\connection.py", line 550, in connect
    sock = self._connect()
  File "C:\anaconda3\envs\RLV\lib\site-packages\redis\connection.py", line 607, in _connect
    raise err
  File "C:\anaconda3\envs\RLV\lib\site-packages\redis\connection.py", line 595, in _connect
    sock.connect(socket_address)
TimeoutError: [WinError 10060] A connection attempt failed because the connected party did not properly respond after a period of time, or established connection failed because connected host has failed to respond

During handling of the above exception, another exception occurred:

Traceback (most recent call last):
  File "C:\anaconda3\envs\RLV\lib\site-packages\ray\reporter.py", line 234, in run
    self.perform_iteration()
  File "C:\anaconda3\envs\RLV\lib\site-packages\ray\reporter.py", line 219, in perform_iteration
    jsonify_asdict(stats),
  File "C:\anaconda3\envs\RLV\lib\site-packages\redis\client.py", line 3052, in publish
    return self.execute_command('PUBLISH', channel, message)
  File "C:\anaconda3\envs\RLV\lib\site-packages\redis\client.py", line 881, in execute_command
    conn = self.connection or pool.get_connection(command_name, **options)
  File "C:\anaconda3\envs\RLV\lib\site-packages\redis\connection.py", line 1178, in get_connection
    connection.connect()
  File "C:\anaconda3\envs\RLV\lib\site-packages\redis\connection.py", line 555, in connect
    raise ConnectionError(self._error_message(e))
redis.exceptions.ConnectionError: Error 10060 connecting to 10.16.234.175:6379. A connection attempt failed because the connected party did not properly respond after a period of time, or established connection failed because connected host has failed to respond.
Traceback (most recent call last):
  File "C:\anaconda3\envs\RLV\lib\site-packages\redis\connection.py", line 550, in connect
    sock = self._connect()
  File "C:\anaconda3\envs\RLV\lib\site-packages\redis\connection.py", line 607, in _connect
    raise err
  File "C:\anaconda3\envs\RLV\lib\site-packages\redis\connection.py", line 595, in _connect
    sock.connect(socket_address)
TimeoutError: [WinError 10060] A connection attempt failed because the connected party did not properly respond after a period of time, or established connection failed because connected host has failed to respond

During handling of the above exception, another exception occurred:

Traceback (most recent call last):
  File "C:\anaconda3\envs\RLV\lib\site-packages\ray\reporter.py", line 234, in run
    self.perform_iteration()
  File "C:\anaconda3\envs\RLV\lib\site-packages\ray\reporter.py", line 219, in perform_iteration
    jsonify_asdict(stats),
  File "C:\anaconda3\envs\RLV\lib\site-packages\redis\client.py", line 3052, in publish
    return self.execute_command('PUBLISH', channel, message)
  File "C:\anaconda3\envs\RLV\lib\site-packages\redis\client.py", line 881, in execute_command
    conn = self.connection or pool.get_connection(command_name, **options)
  File "C:\anaconda3\envs\RLV\lib\site-packages\redis\connection.py", line 1178, in get_connection
    connection.connect()
  File "C:\anaconda3\envs\RLV\lib\site-packages\redis\connection.py", line 555, in connect
    raise ConnectionError(self._error_message(e))
redis.exceptions.ConnectionError: Error 10060 connecting to 10.16.234.175:6379. A connection attempt failed because the connected party did not properly respond after a period of time, or established connection failed because connected host has failed to respond.
Traceback (most recent call last):
  File "C:\anaconda3\envs\RLV\lib\site-packages\redis\connection.py", line 550, in connect
    sock = self._connect()
  File "C:\anaconda3\envs\RLV\lib\site-packages\redis\connection.py", line 607, in _connect
    raise err
  File "C:\anaconda3\envs\RLV\lib\site-packages\redis\connection.py", line 595, in _connect
    sock.connect(socket_address)
TimeoutError: [WinError 10060] A connection attempt failed because the connected party did not properly respond after a period of time, or established connection failed because connected host has failed to respond

During handling of the above exception, another exception occurred:

Traceback (most recent call last):
  File "C:\anaconda3\envs\RLV\lib\site-packages\ray\reporter.py", line 234, in run
    self.perform_iteration()
  File "C:\anaconda3\envs\RLV\lib\site-packages\ray\reporter.py", line 219, in perform_iteration
    jsonify_asdict(stats),
  File "C:\anaconda3\envs\RLV\lib\site-packages\redis\client.py", line 3052, in publish
    return self.execute_command('PUBLISH', channel, message)
  File "C:\anaconda3\envs\RLV\lib\site-packages\redis\client.py", line 881, in execute_command
    conn = self.connection or pool.get_connection(command_name, **options)
  File "C:\anaconda3\envs\RLV\lib\site-packages\redis\connection.py", line 1178, in get_connection
    connection.connect()
  File "C:\anaconda3\envs\RLV\lib\site-packages\redis\connection.py", line 555, in connect
    raise ConnectionError(self._error_message(e))
redis.exceptions.ConnectionError: Error 10060 connecting to 10.16.234.175:6379. A connection attempt failed because the connected party did not properly respond after a period of time, or established connection failed because connected host has failed to respond.
Traceback (most recent call last):
  File "C:\anaconda3\envs\RLV\lib\site-packages\redis\connection.py", line 550, in connect
    sock = self._connect()
  File "C:\anaconda3\envs\RLV\lib\site-packages\redis\connection.py", line 607, in _connect
    raise err
  File "C:\anaconda3\envs\RLV\lib\site-packages\redis\connection.py", line 595, in _connect
    sock.connect(socket_address)
TimeoutError: [WinError 10060] A connection attempt failed because the connected party did not properly respond after a period of time, or established connection failed because connected host has failed to respond

During handling of the above exception, another exception occurred:

Traceback (most recent call last):
  File "C:\anaconda3\envs\RLV\lib\site-packages\ray\reporter.py", line 234, in run
    self.perform_iteration()
  File "C:\anaconda3\envs\RLV\lib\site-packages\ray\reporter.py", line 219, in perform_iteration
    jsonify_asdict(stats),
  File "C:\anaconda3\envs\RLV\lib\site-packages\redis\client.py", line 3052, in publish
    return self.execute_command('PUBLISH', channel, message)
  File "C:\anaconda3\envs\RLV\lib\site-packages\redis\client.py", line 881, in execute_command
    conn = self.connection or pool.get_connection(command_name, **options)
  File "C:\anaconda3\envs\RLV\lib\site-packages\redis\connection.py", line 1178, in get_connection
    connection.connect()
  File "C:\anaconda3\envs\RLV\lib\site-packages\redis\connection.py", line 555, in connect
    raise ConnectionError(self._error_message(e))
redis.exceptions.ConnectionError: Error 10060 connecting to 10.16.234.175:6379. A connection attempt failed because the connected party did not properly respond after a period of time, or established connection failed because connected host has failed to respond.
Traceback (most recent call last):
  File "C:\anaconda3\envs\RLV\lib\site-packages\redis\connection.py", line 550, in connect
    sock = self._connect()
  File "C:\anaconda3\envs\RLV\lib\site-packages\redis\connection.py", line 607, in _connect
    raise err
  File "C:\anaconda3\envs\RLV\lib\site-packages\redis\connection.py", line 595, in _connect
    sock.connect(socket_address)
TimeoutError: [WinError 10060] A connection attempt failed because the connected party did not properly respond after a period of time, or established connection failed because connected host has failed to respond

During handling of the above exception, another exception occurred:

Traceback (most recent call last):
  File "C:\anaconda3\envs\RLV\lib\site-packages\ray\reporter.py", line 234, in run
    self.perform_iteration()
  File "C:\anaconda3\envs\RLV\lib\site-packages\ray\reporter.py", line 219, in perform_iteration
    jsonify_asdict(stats),
  File "C:\anaconda3\envs\RLV\lib\site-packages\redis\client.py", line 3052, in publish
    return self.execute_command('PUBLISH', channel, message)
  File "C:\anaconda3\envs\RLV\lib\site-packages\redis\client.py", line 881, in execute_command
    conn = self.connection or pool.get_connection(command_name, **options)
  File "C:\anaconda3\envs\RLV\lib\site-packages\redis\connection.py", line 1178, in get_connection
    connection.connect()
  File "C:\anaconda3\envs\RLV\lib\site-packages\redis\connection.py", line 555, in connect
    raise ConnectionError(self._error_message(e))
redis.exceptions.ConnectionError: Error 10060 connecting to 10.16.234.175:6379. A connection attempt failed because the connected party did not properly respond after a period of time, or established connection failed because connected host has failed to respond.
Traceback (most recent call last):
  File "C:\anaconda3\envs\RLV\lib\site-packages\redis\connection.py", line 550, in connect
    sock = self._connect()
  File "C:\anaconda3\envs\RLV\lib\site-packages\redis\connection.py", line 607, in _connect
    raise err
  File "C:\anaconda3\envs\RLV\lib\site-packages\redis\connection.py", line 595, in _connect
    sock.connect(socket_address)
TimeoutError: [WinError 10060] A connection attempt failed because the connected party did not properly respond after a period of time, or established connection failed because connected host has failed to respond

During handling of the above exception, another exception occurred:

Traceback (most recent call last):
  File "C:\anaconda3\envs\RLV\lib\site-packages\ray\reporter.py", line 234, in run
    self.perform_iteration()
  File "C:\anaconda3\envs\RLV\lib\site-packages\ray\reporter.py", line 219, in perform_iteration
    jsonify_asdict(stats),
  File "C:\anaconda3\envs\RLV\lib\site-packages\redis\client.py", line 3052, in publish
    return self.execute_command('PUBLISH', channel, message)
  File "C:\anaconda3\envs\RLV\lib\site-packages\redis\client.py", line 881, in execute_command
    conn = self.connection or pool.get_connection(command_name, **options)
  File "C:\anaconda3\envs\RLV\lib\site-packages\redis\connection.py", line 1178, in get_connection
    connection.connect()
  File "C:\anaconda3\envs\RLV\lib\site-packages\redis\connection.py", line 555, in connect
    raise ConnectionError(self._error_message(e))
redis.exceptions.ConnectionError: Error 10060 connecting to 10.16.234.175:6379. A connection attempt failed because the connected party did not properly respond after a period of time, or established connection failed because connected host has failed to respond.
Traceback (most recent call last):
  File "C:\anaconda3\envs\RLV\lib\site-packages\redis\connection.py", line 550, in connect
    sock = self._connect()
  File "C:\anaconda3\envs\RLV\lib\site-packages\redis\connection.py", line 607, in _connect
    raise err
  File "C:\anaconda3\envs\RLV\lib\site-packages\redis\connection.py", line 595, in _connect
    sock.connect(socket_address)
TimeoutError: [WinError 10060] A connection attempt failed because the connected party did not properly respond after a period of time, or established connection failed because connected host has failed to respond

During handling of the above exception, another exception occurred:

Traceback (most recent call last):
  File "C:\anaconda3\envs\RLV\lib\site-packages\ray\reporter.py", line 234, in run
    self.perform_iteration()
  File "C:\anaconda3\envs\RLV\lib\site-packages\ray\reporter.py", line 219, in perform_iteration
    jsonify_asdict(stats),
  File "C:\anaconda3\envs\RLV\lib\site-packages\redis\client.py", line 3052, in publish
    return self.execute_command('PUBLISH', channel, message)
  File "C:\anaconda3\envs\RLV\lib\site-packages\redis\client.py", line 881, in execute_command
    conn = self.connection or pool.get_connection(command_name, **options)
  File "C:\anaconda3\envs\RLV\lib\site-packages\redis\connection.py", line 1178, in get_connection
    connection.connect()
  File "C:\anaconda3\envs\RLV\lib\site-packages\redis\connection.py", line 555, in connect
    raise ConnectionError(self._error_message(e))
redis.exceptions.ConnectionError: Error 10060 connecting to 10.16.234.175:6379. A connection attempt failed because the connected party did not properly respond after a period of time, or established connection failed because connected host has failed to respond.
Traceback (most recent call last):
  File "C:\anaconda3\envs\RLV\lib\site-packages\redis\connection.py", line 550, in connect
    sock = self._connect()
  File "C:\anaconda3\envs\RLV\lib\site-packages\redis\connection.py", line 607, in _connect
    raise err
  File "C:\anaconda3\envs\RLV\lib\site-packages\redis\connection.py", line 595, in _connect
    sock.connect(socket_address)
TimeoutError: [WinError 10060] A connection attempt failed because the connected party did not properly respond after a period of time, or established connection failed because connected host has failed to respond

During handling of the above exception, another exception occurred:

Traceback (most recent call last):
  File "C:\anaconda3\envs\RLV\lib\site-packages\ray\reporter.py", line 234, in run
    self.perform_iteration()
  File "C:\anaconda3\envs\RLV\lib\site-packages\ray\reporter.py", line 219, in perform_iteration
    jsonify_asdict(stats),
  File "C:\anaconda3\envs\RLV\lib\site-packages\redis\client.py", line 3052, in publish
    return self.execute_command('PUBLISH', channel, message)
  File "C:\anaconda3\envs\RLV\lib\site-packages\redis\client.py", line 881, in execute_command
    conn = self.connection or pool.get_connection(command_name, **options)
  File "C:\anaconda3\envs\RLV\lib\site-packages\redis\connection.py", line 1178, in get_connection
    connection.connect()
  File "C:\anaconda3\envs\RLV\lib\site-packages\redis\connection.py", line 555, in connect
    raise ConnectionError(self._error_message(e))
redis.exceptions.ConnectionError: Error 10060 connecting to 10.16.234.175:6379. A connection attempt failed because the connected party did not properly respond after a period of time, or established connection failed because connected host has failed to respond.
Traceback (most recent call last):
  File "C:\anaconda3\envs\RLV\lib\site-packages\redis\connection.py", line 550, in connect
    sock = self._connect()
  File "C:\anaconda3\envs\RLV\lib\site-packages\redis\connection.py", line 607, in _connect
    raise err
  File "C:\anaconda3\envs\RLV\lib\site-packages\redis\connection.py", line 595, in _connect
    sock.connect(socket_address)
TimeoutError: [WinError 10060] A connection attempt failed because the connected party did not properly respond after a period of time, or established connection failed because connected host has failed to respond

During handling of the above exception, another exception occurred:

Traceback (most recent call last):
  File "C:\anaconda3\envs\RLV\lib\site-packages\ray\reporter.py", line 234, in run
    self.perform_iteration()
  File "C:\anaconda3\envs\RLV\lib\site-packages\ray\reporter.py", line 219, in perform_iteration
    jsonify_asdict(stats),
  File "C:\anaconda3\envs\RLV\lib\site-packages\redis\client.py", line 3052, in publish
    return self.execute_command('PUBLISH', channel, message)
  File "C:\anaconda3\envs\RLV\lib\site-packages\redis\client.py", line 881, in execute_command
    conn = self.connection or pool.get_connection(command_name, **options)
  File "C:\anaconda3\envs\RLV\lib\site-packages\redis\connection.py", line 1178, in get_connection
    connection.connect()
  File "C:\anaconda3\envs\RLV\lib\site-packages\redis\connection.py", line 555, in connect
    raise ConnectionError(self._error_message(e))
redis.exceptions.ConnectionError: Error 10060 connecting to 10.16.234.175:6379. A connection attempt failed because the connected party did not properly respond after a period of time, or established connection failed because connected host has failed to respond.
Traceback (most recent call last):
  File "C:\anaconda3\envs\RLV\lib\site-packages\redis\connection.py", line 550, in connect
    sock = self._connect()
  File "C:\anaconda3\envs\RLV\lib\site-packages\redis\connection.py", line 607, in _connect
    raise err
  File "C:\anaconda3\envs\RLV\lib\site-packages\redis\connection.py", line 595, in _connect
    sock.connect(socket_address)
TimeoutError: [WinError 10060] A connection attempt failed because the connected party did not properly respond after a period of time, or established connection failed because connected host has failed to respond

During handling of the above exception, another exception occurred:

Traceback (most recent call last):
  File "C:\anaconda3\envs\RLV\lib\site-packages\ray\reporter.py", line 234, in run
    self.perform_iteration()
  File "C:\anaconda3\envs\RLV\lib\site-packages\ray\reporter.py", line 219, in perform_iteration
    jsonify_asdict(stats),
  File "C:\anaconda3\envs\RLV\lib\site-packages\redis\client.py", line 3052, in publish
    return self.execute_command('PUBLISH', channel, message)
  File "C:\anaconda3\envs\RLV\lib\site-packages\redis\client.py", line 881, in execute_command
    conn = self.connection or pool.get_connection(command_name, **options)
  File "C:\anaconda3\envs\RLV\lib\site-packages\redis\connection.py", line 1178, in get_connection
    connection.connect()
  File "C:\anaconda3\envs\RLV\lib\site-packages\redis\connection.py", line 555, in connect
    raise ConnectionError(self._error_message(e))
redis.exceptions.ConnectionError: Error 10060 connecting to 10.16.234.175:6379. A connection attempt failed because the connected party did not properly respond after a period of time, or established connection failed because connected host has failed to respond.
Traceback (most recent call last):
  File "C:\anaconda3\envs\RLV\lib\site-packages\redis\connection.py", line 550, in connect
    sock = self._connect()
  File "C:\anaconda3\envs\RLV\lib\site-packages\redis\connection.py", line 607, in _connect
    raise err
  File "C:\anaconda3\envs\RLV\lib\site-packages\redis\connection.py", line 595, in _connect
    sock.connect(socket_address)
TimeoutError: [WinError 10060] A connection attempt failed because the connected party did not properly respond after a period of time, or established connection failed because connected host has failed to respond

During handling of the above exception, another exception occurred:

Traceback (most recent call last):
  File "C:\anaconda3\envs\RLV\lib\site-packages\ray\reporter.py", line 234, in run
    self.perform_iteration()
  File "C:\anaconda3\envs\RLV\lib\site-packages\ray\reporter.py", line 219, in perform_iteration
    jsonify_asdict(stats),
  File "C:\anaconda3\envs\RLV\lib\site-packages\redis\client.py", line 3052, in publish
    return self.execute_command('PUBLISH', channel, message)
  File "C:\anaconda3\envs\RLV\lib\site-packages\redis\client.py", line 881, in execute_command
    conn = self.connection or pool.get_connection(command_name, **options)
  File "C:\anaconda3\envs\RLV\lib\site-packages\redis\connection.py", line 1178, in get_connection
    connection.connect()
  File "C:\anaconda3\envs\RLV\lib\site-packages\redis\connection.py", line 555, in connect
    raise ConnectionError(self._error_message(e))
redis.exceptions.ConnectionError: Error 10060 connecting to 10.16.234.175:6379. A connection attempt failed because the connected party did not properly respond after a period of time, or established connection failed because connected host has failed to respond.
Traceback (most recent call last):
  File "C:\anaconda3\envs\RLV\lib\site-packages\redis\connection.py", line 550, in connect
    sock = self._connect()
  File "C:\anaconda3\envs\RLV\lib\site-packages\redis\connection.py", line 607, in _connect
    raise err
  File "C:\anaconda3\envs\RLV\lib\site-packages\redis\connection.py", line 595, in _connect
    sock.connect(socket_address)
TimeoutError: [WinError 10060] A connection attempt failed because the connected party did not properly respond after a period of time, or established connection failed because connected host has failed to respond

During handling of the above exception, another exception occurred:

Traceback (most recent call last):
  File "C:\anaconda3\envs\RLV\lib\site-packages\ray\reporter.py", line 234, in run
    self.perform_iteration()
  File "C:\anaconda3\envs\RLV\lib\site-packages\ray\reporter.py", line 219, in perform_iteration
    jsonify_asdict(stats),
  File "C:\anaconda3\envs\RLV\lib\site-packages\redis\client.py", line 3052, in publish
    return self.execute_command('PUBLISH', channel, message)
  File "C:\anaconda3\envs\RLV\lib\site-packages\redis\client.py", line 881, in execute_command
    conn = self.connection or pool.get_connection(command_name, **options)
  File "C:\anaconda3\envs\RLV\lib\site-packages\redis\connection.py", line 1178, in get_connection
    connection.connect()
  File "C:\anaconda3\envs\RLV\lib\site-packages\redis\connection.py", line 555, in connect
    raise ConnectionError(self._error_message(e))
redis.exceptions.ConnectionError: Error 10060 connecting to 10.16.234.175:6379. A connection attempt failed because the connected party did not properly respond after a period of time, or established connection failed because connected host has failed to respond.
Traceback (most recent call last):
  File "C:\anaconda3\envs\RLV\lib\site-packages\redis\connection.py", line 550, in connect
    sock = self._connect()
  File "C:\anaconda3\envs\RLV\lib\site-packages\redis\connection.py", line 607, in _connect
    raise err
  File "C:\anaconda3\envs\RLV\lib\site-packages\redis\connection.py", line 595, in _connect
    sock.connect(socket_address)
TimeoutError: [WinError 10060] A connection attempt failed because the connected party did not properly respond after a period of time, or established connection failed because connected host has failed to respond

During handling of the above exception, another exception occurred:

Traceback (most recent call last):
  File "C:\anaconda3\envs\RLV\lib\site-packages\ray\reporter.py", line 234, in run
    self.perform_iteration()
  File "C:\anaconda3\envs\RLV\lib\site-packages\ray\reporter.py", line 219, in perform_iteration
    jsonify_asdict(stats),
  File "C:\anaconda3\envs\RLV\lib\site-packages\redis\client.py", line 3052, in publish
    return self.execute_command('PUBLISH', channel, message)
  File "C:\anaconda3\envs\RLV\lib\site-packages\redis\client.py", line 881, in execute_command
    conn = self.connection or pool.get_connection(command_name, **options)
  File "C:\anaconda3\envs\RLV\lib\site-packages\redis\connection.py", line 1178, in get_connection
    connection.connect()
  File "C:\anaconda3\envs\RLV\lib\site-packages\redis\connection.py", line 555, in connect
    raise ConnectionError(self._error_message(e))
redis.exceptions.ConnectionError: Error 10060 connecting to 10.16.234.175:6379. A connection attempt failed because the connected party did not properly respond after a period of time, or established connection failed because connected host has failed to respond.
Traceback (most recent call last):
  File "C:\anaconda3\envs\RLV\lib\site-packages\redis\connection.py", line 550, in connect
    sock = self._connect()
  File "C:\anaconda3\envs\RLV\lib\site-packages\redis\connection.py", line 607, in _connect
    raise err
  File "C:\anaconda3\envs\RLV\lib\site-packages\redis\connection.py", line 595, in _connect
    sock.connect(socket_address)
TimeoutError: [WinError 10060] A connection attempt failed because the connected party did not properly respond after a period of time, or established connection failed because connected host has failed to respond

During handling of the above exception, another exception occurred:

Traceback (most recent call last):
  File "C:\anaconda3\envs\RLV\lib\site-packages\ray\reporter.py", line 234, in run
    self.perform_iteration()
  File "C:\anaconda3\envs\RLV\lib\site-packages\ray\reporter.py", line 219, in perform_iteration
    jsonify_asdict(stats),
  File "C:\anaconda3\envs\RLV\lib\site-packages\redis\client.py", line 3052, in publish
    return self.execute_command('PUBLISH', channel, message)
  File "C:\anaconda3\envs\RLV\lib\site-packages\redis\client.py", line 881, in execute_command
    conn = self.connection or pool.get_connection(command_name, **options)
  File "C:\anaconda3\envs\RLV\lib\site-packages\redis\connection.py", line 1178, in get_connection
    connection.connect()
  File "C:\anaconda3\envs\RLV\lib\site-packages\redis\connection.py", line 555, in connect
    raise ConnectionError(self._error_message(e))
redis.exceptions.ConnectionError: Error 10060 connecting to 10.16.234.175:6379. A connection attempt failed because the connected party did not properly respond after a period of time, or established connection failed because connected host has failed to respond.
Traceback (most recent call last):
  File "C:\anaconda3\envs\RLV\lib\site-packages\redis\connection.py", line 550, in connect
    sock = self._connect()
  File "C:\anaconda3\envs\RLV\lib\site-packages\redis\connection.py", line 607, in _connect
    raise err
  File "C:\anaconda3\envs\RLV\lib\site-packages\redis\connection.py", line 595, in _connect
    sock.connect(socket_address)
TimeoutError: [WinError 10060] A connection attempt failed because the connected party did not properly respond after a period of time, or established connection failed because connected host has failed to respond

During handling of the above exception, another exception occurred:

Traceback (most recent call last):
  File "C:\anaconda3\envs\RLV\lib\site-packages\ray\reporter.py", line 234, in run
    self.perform_iteration()
  File "C:\anaconda3\envs\RLV\lib\site-packages\ray\reporter.py", line 219, in perform_iteration
    jsonify_asdict(stats),
  File "C:\anaconda3\envs\RLV\lib\site-packages\redis\client.py", line 3052, in publish
    return self.execute_command('PUBLISH', channel, message)
  File "C:\anaconda3\envs\RLV\lib\site-packages\redis\client.py", line 881, in execute_command
    conn = self.connection or pool.get_connection(command_name, **options)
  File "C:\anaconda3\envs\RLV\lib\site-packages\redis\connection.py", line 1178, in get_connection
    connection.connect()
  File "C:\anaconda3\envs\RLV\lib\site-packages\redis\connection.py", line 555, in connect
    raise ConnectionError(self._error_message(e))
redis.exceptions.ConnectionError: Error 10060 connecting to 10.16.234.175:6379. A connection attempt failed because the connected party did not properly respond after a period of time, or established connection failed because connected host has failed to respond.
Traceback (most recent call last):
  File "C:\anaconda3\envs\RLV\lib\site-packages\redis\connection.py", line 550, in connect
    sock = self._connect()
  File "C:\anaconda3\envs\RLV\lib\site-packages\redis\connection.py", line 607, in _connect
    raise err
  File "C:\anaconda3\envs\RLV\lib\site-packages\redis\connection.py", line 595, in _connect
    sock.connect(socket_address)
TimeoutError: [WinError 10060] A connection attempt failed because the connected party did not properly respond after a period of time, or established connection failed because connected host has failed to respond

During handling of the above exception, another exception occurred:

Traceback (most recent call last):
  File "C:\anaconda3\envs\RLV\lib\site-packages\ray\reporter.py", line 234, in run
    self.perform_iteration()
  File "C:\anaconda3\envs\RLV\lib\site-packages\ray\reporter.py", line 219, in perform_iteration
    jsonify_asdict(stats),
  File "C:\anaconda3\envs\RLV\lib\site-packages\redis\client.py", line 3052, in publish
    return self.execute_command('PUBLISH', channel, message)
  File "C:\anaconda3\envs\RLV\lib\site-packages\redis\client.py", line 881, in execute_command
    conn = self.connection or pool.get_connection(command_name, **options)
  File "C:\anaconda3\envs\RLV\lib\site-packages\redis\connection.py", line 1178, in get_connection
    connection.connect()
  File "C:\anaconda3\envs\RLV\lib\site-packages\redis\connection.py", line 555, in connect
    raise ConnectionError(self._error_message(e))
redis.exceptions.ConnectionError: Error 10060 connecting to 10.16.234.175:6379. A connection attempt failed because the connected party did not properly respond after a period of time, or established connection failed because connected host has failed to respond.
Traceback (most recent call last):
  File "C:\anaconda3\envs\RLV\lib\site-packages\redis\connection.py", line 550, in connect
    sock = self._connect()
  File "C:\anaconda3\envs\RLV\lib\site-packages\redis\connection.py", line 607, in _connect
    raise err
  File "C:\anaconda3\envs\RLV\lib\site-packages\redis\connection.py", line 595, in _connect
    sock.connect(socket_address)
TimeoutError: [WinError 10060] A connection attempt failed because the connected party did not properly respond after a period of time, or established connection failed because connected host has failed to respond

During handling of the above exception, another exception occurred:

Traceback (most recent call last):
  File "C:\anaconda3\envs\RLV\lib\site-packages\ray\reporter.py", line 234, in run
    self.perform_iteration()
  File "C:\anaconda3\envs\RLV\lib\site-packages\ray\reporter.py", line 219, in perform_iteration
    jsonify_asdict(stats),
  File "C:\anaconda3\envs\RLV\lib\site-packages\redis\client.py", line 3052, in publish
    return self.execute_command('PUBLISH', channel, message)
  File "C:\anaconda3\envs\RLV\lib\site-packages\redis\client.py", line 881, in execute_command
    conn = self.connection or pool.get_connection(command_name, **options)
  File "C:\anaconda3\envs\RLV\lib\site-packages\redis\connection.py", line 1178, in get_connection
    connection.connect()
  File "C:\anaconda3\envs\RLV\lib\site-packages\redis\connection.py", line 555, in connect
    raise ConnectionError(self._error_message(e))
redis.exceptions.ConnectionError: Error 10060 connecting to 10.16.234.175:6379. A connection attempt failed because the connected party did not properly respond after a period of time, or established connection failed because connected host has failed to respond.
Traceback (most recent call last):
  File "C:\anaconda3\envs\RLV\lib\site-packages\redis\connection.py", line 550, in connect
    sock = self._connect()
  File "C:\anaconda3\envs\RLV\lib\site-packages\redis\connection.py", line 607, in _connect
    raise err
  File "C:\anaconda3\envs\RLV\lib\site-packages\redis\connection.py", line 595, in _connect
    sock.connect(socket_address)
TimeoutError: [WinError 10060] A connection attempt failed because the connected party did not properly respond after a period of time, or established connection failed because connected host has failed to respond

During handling of the above exception, another exception occurred:

Traceback (most recent call last):
  File "C:\anaconda3\envs\RLV\lib\site-packages\ray\reporter.py", line 234, in run
    self.perform_iteration()
  File "C:\anaconda3\envs\RLV\lib\site-packages\ray\reporter.py", line 219, in perform_iteration
    jsonify_asdict(stats),
  File "C:\anaconda3\envs\RLV\lib\site-packages\redis\client.py", line 3052, in publish
    return self.execute_command('PUBLISH', channel, message)
  File "C:\anaconda3\envs\RLV\lib\site-packages\redis\client.py", line 881, in execute_command
    conn = self.connection or pool.get_connection(command_name, **options)
  File "C:\anaconda3\envs\RLV\lib\site-packages\redis\connection.py", line 1178, in get_connection
    connection.connect()
  File "C:\anaconda3\envs\RLV\lib\site-packages\redis\connection.py", line 555, in connect
    raise ConnectionError(self._error_message(e))
redis.exceptions.ConnectionError: Error 10060 connecting to 10.16.234.175:6379. A connection attempt failed because the connected party did not properly respond after a period of time, or established connection failed because connected host has failed to respond.
Traceback (most recent call last):
  File "C:\anaconda3\envs\RLV\lib\site-packages\redis\connection.py", line 550, in connect
    sock = self._connect()
  File "C:\anaconda3\envs\RLV\lib\site-packages\redis\connection.py", line 607, in _connect
    raise err
  File "C:\anaconda3\envs\RLV\lib\site-packages\redis\connection.py", line 595, in _connect
    sock.connect(socket_address)
TimeoutError: [WinError 10060] A connection attempt failed because the connected party did not properly respond after a period of time, or established connection failed because connected host has failed to respond

During handling of the above exception, another exception occurred:

Traceback (most recent call last):
  File "C:\anaconda3\envs\RLV\lib\site-packages\ray\reporter.py", line 234, in run
    self.perform_iteration()
  File "C:\anaconda3\envs\RLV\lib\site-packages\ray\reporter.py", line 219, in perform_iteration
    jsonify_asdict(stats),
  File "C:\anaconda3\envs\RLV\lib\site-packages\redis\client.py", line 3052, in publish
    return self.execute_command('PUBLISH', channel, message)
  File "C:\anaconda3\envs\RLV\lib\site-packages\redis\client.py", line 881, in execute_command
    conn = self.connection or pool.get_connection(command_name, **options)
  File "C:\anaconda3\envs\RLV\lib\site-packages\redis\connection.py", line 1178, in get_connection
    connection.connect()
  File "C:\anaconda3\envs\RLV\lib\site-packages\redis\connection.py", line 555, in connect
    raise ConnectionError(self._error_message(e))
redis.exceptions.ConnectionError: Error 10060 connecting to 10.16.234.175:6379. A connection attempt failed because the connected party did not properly respond after a period of time, or established connection failed because connected host has failed to respond.
Traceback (most recent call last):
  File "C:\anaconda3\envs\RLV\lib\site-packages\redis\connection.py", line 550, in connect
    sock = self._connect()
  File "C:\anaconda3\envs\RLV\lib\site-packages\redis\connection.py", line 607, in _connect
    raise err
  File "C:\anaconda3\envs\RLV\lib\site-packages\redis\connection.py", line 595, in _connect
    sock.connect(socket_address)
TimeoutError: [WinError 10060] A connection attempt failed because the connected party did not properly respond after a period of time, or established connection failed because connected host has failed to respond

During handling of the above exception, another exception occurred:

Traceback (most recent call last):
  File "C:\anaconda3\envs\RLV\lib\site-packages\ray\reporter.py", line 234, in run
    self.perform_iteration()
  File "C:\anaconda3\envs\RLV\lib\site-packages\ray\reporter.py", line 219, in perform_iteration
    jsonify_asdict(stats),
  File "C:\anaconda3\envs\RLV\lib\site-packages\redis\client.py", line 3052, in publish
    return self.execute_command('PUBLISH', channel, message)
  File "C:\anaconda3\envs\RLV\lib\site-packages\redis\client.py", line 881, in execute_command
    conn = self.connection or pool.get_connection(command_name, **options)
  File "C:\anaconda3\envs\RLV\lib\site-packages\redis\connection.py", line 1178, in get_connection
    connection.connect()
  File "C:\anaconda3\envs\RLV\lib\site-packages\redis\connection.py", line 555, in connect
    raise ConnectionError(self._error_message(e))
redis.exceptions.ConnectionError: Error 10060 connecting to 10.16.234.175:6379. A connection attempt failed because the connected party did not properly respond after a period of time, or established connection failed because connected host has failed to respond.
Traceback (most recent call last):
  File "C:\anaconda3\envs\RLV\lib\site-packages\redis\connection.py", line 550, in connect
    sock = self._connect()
  File "C:\anaconda3\envs\RLV\lib\site-packages\redis\connection.py", line 607, in _connect
    raise err
  File "C:\anaconda3\envs\RLV\lib\site-packages\redis\connection.py", line 595, in _connect
    sock.connect(socket_address)
TimeoutError: [WinError 10060] A connection attempt failed because the connected party did not properly respond after a period of time, or established connection failed because connected host has failed to respond

During handling of the above exception, another exception occurred:

Traceback (most recent call last):
  File "C:\anaconda3\envs\RLV\lib\site-packages\ray\reporter.py", line 234, in run
    self.perform_iteration()
  File "C:\anaconda3\envs\RLV\lib\site-packages\ray\reporter.py", line 219, in perform_iteration
    jsonify_asdict(stats),
  File "C:\anaconda3\envs\RLV\lib\site-packages\redis\client.py", line 3052, in publish
    return self.execute_command('PUBLISH', channel, message)
  File "C:\anaconda3\envs\RLV\lib\site-packages\redis\client.py", line 881, in execute_command
    conn = self.connection or pool.get_connection(command_name, **options)
  File "C:\anaconda3\envs\RLV\lib\site-packages\redis\connection.py", line 1178, in get_connection
    connection.connect()
  File "C:\anaconda3\envs\RLV\lib\site-packages\redis\connection.py", line 555, in connect
    raise ConnectionError(self._error_message(e))
redis.exceptions.ConnectionError: Error 10060 connecting to 10.16.234.175:6379. A connection attempt failed because the connected party did not properly respond after a period of time, or established connection failed because connected host has failed to respond.
Traceback (most recent call last):
  File "C:\anaconda3\envs\RLV\lib\site-packages\redis\connection.py", line 550, in connect
    sock = self._connect()
  File "C:\anaconda3\envs\RLV\lib\site-packages\redis\connection.py", line 607, in _connect
    raise err
  File "C:\anaconda3\envs\RLV\lib\site-packages\redis\connection.py", line 595, in _connect
    sock.connect(socket_address)
TimeoutError: [WinError 10060] A connection attempt failed because the connected party did not properly respond after a period of time, or established connection failed because connected host has failed to respond

During handling of the above exception, another exception occurred:

Traceback (most recent call last):
  File "C:\anaconda3\envs\RLV\lib\site-packages\ray\reporter.py", line 234, in run
    self.perform_iteration()
  File "C:\anaconda3\envs\RLV\lib\site-packages\ray\reporter.py", line 219, in perform_iteration
    jsonify_asdict(stats),
  File "C:\anaconda3\envs\RLV\lib\site-packages\redis\client.py", line 3052, in publish
    return self.execute_command('PUBLISH', channel, message)
  File "C:\anaconda3\envs\RLV\lib\site-packages\redis\client.py", line 881, in execute_command
    conn = self.connection or pool.get_connection(command_name, **options)
  File "C:\anaconda3\envs\RLV\lib\site-packages\redis\connection.py", line 1178, in get_connection
    connection.connect()
  File "C:\anaconda3\envs\RLV\lib\site-packages\redis\connection.py", line 555, in connect
    raise ConnectionError(self._error_message(e))
redis.exceptions.ConnectionError: Error 10060 connecting to 10.16.234.175:6379. A connection attempt failed because the connected party did not properly respond after a period of time, or established connection failed because connected host has failed to respond.
Traceback (most recent call last):
  File "C:\anaconda3\envs\RLV\lib\site-packages\redis\connection.py", line 550, in connect
    sock = self._connect()
  File "C:\anaconda3\envs\RLV\lib\site-packages\redis\connection.py", line 607, in _connect
    raise err
  File "C:\anaconda3\envs\RLV\lib\site-packages\redis\connection.py", line 595, in _connect
    sock.connect(socket_address)
TimeoutError: [WinError 10060] A connection attempt failed because the connected party did not properly respond after a period of time, or established connection failed because connected host has failed to respond

During handling of the above exception, another exception occurred:

Traceback (most recent call last):
  File "C:\anaconda3\envs\RLV\lib\site-packages\ray\reporter.py", line 234, in run
    self.perform_iteration()
  File "C:\anaconda3\envs\RLV\lib\site-packages\ray\reporter.py", line 219, in perform_iteration
    jsonify_asdict(stats),
  File "C:\anaconda3\envs\RLV\lib\site-packages\redis\client.py", line 3052, in publish
    return self.execute_command('PUBLISH', channel, message)
  File "C:\anaconda3\envs\RLV\lib\site-packages\redis\client.py", line 881, in execute_command
    conn = self.connection or pool.get_connection(command_name, **options)
  File "C:\anaconda3\envs\RLV\lib\site-packages\redis\connection.py", line 1178, in get_connection
    connection.connect()
  File "C:\anaconda3\envs\RLV\lib\site-packages\redis\connection.py", line 555, in connect
    raise ConnectionError(self._error_message(e))
redis.exceptions.ConnectionError: Error 10060 connecting to 10.16.234.175:6379. A connection attempt failed because the connected party did not properly respond after a period of time, or established connection failed because connected host has failed to respond.
Traceback (most recent call last):
  File "C:\anaconda3\envs\RLV\lib\site-packages\redis\connection.py", line 550, in connect
    sock = self._connect()
  File "C:\anaconda3\envs\RLV\lib\site-packages\redis\connection.py", line 607, in _connect
    raise err
  File "C:\anaconda3\envs\RLV\lib\site-packages\redis\connection.py", line 595, in _connect
    sock.connect(socket_address)
TimeoutError: [WinError 10060] A connection attempt failed because the connected party did not properly respond after a period of time, or established connection failed because connected host has failed to respond

During handling of the above exception, another exception occurred:

Traceback (most recent call last):
  File "C:\anaconda3\envs\RLV\lib\site-packages\ray\reporter.py", line 234, in run
    self.perform_iteration()
  File "C:\anaconda3\envs\RLV\lib\site-packages\ray\reporter.py", line 219, in perform_iteration
    jsonify_asdict(stats),
  File "C:\anaconda3\envs\RLV\lib\site-packages\redis\client.py", line 3052, in publish
    return self.execute_command('PUBLISH', channel, message)
  File "C:\anaconda3\envs\RLV\lib\site-packages\redis\client.py", line 881, in execute_command
    conn = self.connection or pool.get_connection(command_name, **options)
  File "C:\anaconda3\envs\RLV\lib\site-packages\redis\connection.py", line 1178, in get_connection
    connection.connect()
  File "C:\anaconda3\envs\RLV\lib\site-packages\redis\connection.py", line 555, in connect
    raise ConnectionError(self._error_message(e))
redis.exceptions.ConnectionError: Error 10060 connecting to 10.16.234.175:6379. A connection attempt failed because the connected party did not properly respond after a period of time, or established connection failed because connected host has failed to respond.
Traceback (most recent call last):
  File "C:\anaconda3\envs\RLV\lib\site-packages\redis\connection.py", line 550, in connect
    sock = self._connect()
  File "C:\anaconda3\envs\RLV\lib\site-packages\redis\connection.py", line 607, in _connect
    raise err
  File "C:\anaconda3\envs\RLV\lib\site-packages\redis\connection.py", line 595, in _connect
    sock.connect(socket_address)
TimeoutError: [WinError 10060] A connection attempt failed because the connected party did not properly respond after a period of time, or established connection failed because connected host has failed to respond

During handling of the above exception, another exception occurred:

Traceback (most recent call last):
  File "C:\anaconda3\envs\RLV\lib\site-packages\ray\reporter.py", line 234, in run
    self.perform_iteration()
  File "C:\anaconda3\envs\RLV\lib\site-packages\ray\reporter.py", line 219, in perform_iteration
    jsonify_asdict(stats),
  File "C:\anaconda3\envs\RLV\lib\site-packages\redis\client.py", line 3052, in publish
    return self.execute_command('PUBLISH', channel, message)
  File "C:\anaconda3\envs\RLV\lib\site-packages\redis\client.py", line 881, in execute_command
    conn = self.connection or pool.get_connection(command_name, **options)
  File "C:\anaconda3\envs\RLV\lib\site-packages\redis\connection.py", line 1178, in get_connection
    connection.connect()
  File "C:\anaconda3\envs\RLV\lib\site-packages\redis\connection.py", line 555, in connect
    raise ConnectionError(self._error_message(e))
redis.exceptions.ConnectionError: Error 10060 connecting to 10.16.234.175:6379. A connection attempt failed because the connected party did not properly respond after a period of time, or established connection failed because connected host has failed to respond.
Traceback (most recent call last):
  File "C:\anaconda3\envs\RLV\lib\site-packages\redis\connection.py", line 550, in connect
    sock = self._connect()
  File "C:\anaconda3\envs\RLV\lib\site-packages\redis\connection.py", line 607, in _connect
    raise err
  File "C:\anaconda3\envs\RLV\lib\site-packages\redis\connection.py", line 595, in _connect
    sock.connect(socket_address)
TimeoutError: [WinError 10060] A connection attempt failed because the connected party did not properly respond after a period of time, or established connection failed because connected host has failed to respond

During handling of the above exception, another exception occurred:

Traceback (most recent call last):
  File "C:\anaconda3\envs\RLV\lib\site-packages\ray\reporter.py", line 234, in run
    self.perform_iteration()
  File "C:\anaconda3\envs\RLV\lib\site-packages\ray\reporter.py", line 219, in perform_iteration
    jsonify_asdict(stats),
  File "C:\anaconda3\envs\RLV\lib\site-packages\redis\client.py", line 3052, in publish
    return self.execute_command('PUBLISH', channel, message)
  File "C:\anaconda3\envs\RLV\lib\site-packages\redis\client.py", line 881, in execute_command
    conn = self.connection or pool.get_connection(command_name, **options)
  File "C:\anaconda3\envs\RLV\lib\site-packages\redis\connection.py", line 1178, in get_connection
    connection.connect()
  File "C:\anaconda3\envs\RLV\lib\site-packages\redis\connection.py", line 555, in connect
    raise ConnectionError(self._error_message(e))
redis.exceptions.ConnectionError: Error 10060 connecting to 10.16.234.175:6379. A connection attempt failed because the connected party did not properly respond after a period of time, or established connection failed because connected host has failed to respond.
Traceback (most recent call last):
  File "C:\anaconda3\envs\RLV\lib\site-packages\redis\connection.py", line 550, in connect
    sock = self._connect()
  File "C:\anaconda3\envs\RLV\lib\site-packages\redis\connection.py", line 607, in _connect
    raise err
  File "C:\anaconda3\envs\RLV\lib\site-packages\redis\connection.py", line 595, in _connect
    sock.connect(socket_address)
TimeoutError: [WinError 10060] A connection attempt failed because the connected party did not properly respond after a period of time, or established connection failed because connected host has failed to respond

During handling of the above exception, another exception occurred:

Traceback (most recent call last):
  File "C:\anaconda3\envs\RLV\lib\site-packages\ray\reporter.py", line 234, in run
    self.perform_iteration()
  File "C:\anaconda3\envs\RLV\lib\site-packages\ray\reporter.py", line 219, in perform_iteration
    jsonify_asdict(stats),
  File "C:\anaconda3\envs\RLV\lib\site-packages\redis\client.py", line 3052, in publish
    return self.execute_command('PUBLISH', channel, message)
  File "C:\anaconda3\envs\RLV\lib\site-packages\redis\client.py", line 881, in execute_command
    conn = self.connection or pool.get_connection(command_name, **options)
  File "C:\anaconda3\envs\RLV\lib\site-packages\redis\connection.py", line 1178, in get_connection
    connection.connect()
  File "C:\anaconda3\envs\RLV\lib\site-packages\redis\connection.py", line 555, in connect
    raise ConnectionError(self._error_message(e))
redis.exceptions.ConnectionError: Error 10060 connecting to 10.16.234.175:6379. A connection attempt failed because the connected party did not properly respond after a period of time, or established connection failed because connected host has failed to respond.
Traceback (most recent call last):
  File "C:\anaconda3\envs\RLV\lib\site-packages\redis\connection.py", line 550, in connect
    sock = self._connect()
  File "C:\anaconda3\envs\RLV\lib\site-packages\redis\connection.py", line 607, in _connect
    raise err
  File "C:\anaconda3\envs\RLV\lib\site-packages\redis\connection.py", line 595, in _connect
    sock.connect(socket_address)
TimeoutError: [WinError 10060] A connection attempt failed because the connected party did not properly respond after a period of time, or established connection failed because connected host has failed to respond

During handling of the above exception, another exception occurred:

Traceback (most recent call last):
  File "C:\anaconda3\envs\RLV\lib\site-packages\ray\reporter.py", line 234, in run
    self.perform_iteration()
  File "C:\anaconda3\envs\RLV\lib\site-packages\ray\reporter.py", line 219, in perform_iteration
    jsonify_asdict(stats),
  File "C:\anaconda3\envs\RLV\lib\site-packages\redis\client.py", line 3052, in publish
    return self.execute_command('PUBLISH', channel, message)
  File "C:\anaconda3\envs\RLV\lib\site-packages\redis\client.py", line 881, in execute_command
    conn = self.connection or pool.get_connection(command_name, **options)
  File "C:\anaconda3\envs\RLV\lib\site-packages\redis\connection.py", line 1178, in get_connection
    connection.connect()
  File "C:\anaconda3\envs\RLV\lib\site-packages\redis\connection.py", line 555, in connect
    raise ConnectionError(self._error_message(e))
redis.exceptions.ConnectionError: Error 10060 connecting to 10.16.234.175:6379. A connection attempt failed because the connected party did not properly respond after a period of time, or established connection failed because connected host has failed to respond.
Traceback (most recent call last):
  File "C:\anaconda3\envs\RLV\lib\site-packages\redis\connection.py", line 550, in connect
    sock = self._connect()
  File "C:\anaconda3\envs\RLV\lib\site-packages\redis\connection.py", line 607, in _connect
    raise err
  File "C:\anaconda3\envs\RLV\lib\site-packages\redis\connection.py", line 595, in _connect
    sock.connect(socket_address)
TimeoutError: [WinError 10060] A connection attempt failed because the connected party did not properly respond after a period of time, or established connection failed because connected host has failed to respond

During handling of the above exception, another exception occurred:

Traceback (most recent call last):
  File "C:\anaconda3\envs\RLV\lib\site-packages\ray\reporter.py", line 234, in run
    self.perform_iteration()
  File "C:\anaconda3\envs\RLV\lib\site-packages\ray\reporter.py", line 219, in perform_iteration
    jsonify_asdict(stats),
  File "C:\anaconda3\envs\RLV\lib\site-packages\redis\client.py", line 3052, in publish
    return self.execute_command('PUBLISH', channel, message)
  File "C:\anaconda3\envs\RLV\lib\site-packages\redis\client.py", line 881, in execute_command
    conn = self.connection or pool.get_connection(command_name, **options)
  File "C:\anaconda3\envs\RLV\lib\site-packages\redis\connection.py", line 1178, in get_connection
    connection.connect()
  File "C:\anaconda3\envs\RLV\lib\site-packages\redis\connection.py", line 555, in connect
    raise ConnectionError(self._error_message(e))
redis.exceptions.ConnectionError: Error 10060 connecting to 10.16.234.175:6379. A connection attempt failed because the connected party did not properly respond after a period of time, or established connection failed because connected host has failed to respond.
Traceback (most recent call last):
  File "C:\anaconda3\envs\RLV\lib\site-packages\redis\connection.py", line 550, in connect
    sock = self._connect()
  File "C:\anaconda3\envs\RLV\lib\site-packages\redis\connection.py", line 607, in _connect
    raise err
  File "C:\anaconda3\envs\RLV\lib\site-packages\redis\connection.py", line 595, in _connect
    sock.connect(socket_address)
TimeoutError: [WinError 10060] A connection attempt failed because the connected party did not properly respond after a period of time, or established connection failed because connected host has failed to respond

During handling of the above exception, another exception occurred:

Traceback (most recent call last):
  File "C:\anaconda3\envs\RLV\lib\site-packages\ray\reporter.py", line 234, in run
    self.perform_iteration()
  File "C:\anaconda3\envs\RLV\lib\site-packages\ray\reporter.py", line 219, in perform_iteration
    jsonify_asdict(stats),
  File "C:\anaconda3\envs\RLV\lib\site-packages\redis\client.py", line 3052, in publish
    return self.execute_command('PUBLISH', channel, message)
  File "C:\anaconda3\envs\RLV\lib\site-packages\redis\client.py", line 881, in execute_command
    conn = self.connection or pool.get_connection(command_name, **options)
  File "C:\anaconda3\envs\RLV\lib\site-packages\redis\connection.py", line 1178, in get_connection
    connection.connect()
  File "C:\anaconda3\envs\RLV\lib\site-packages\redis\connection.py", line 555, in connect
    raise ConnectionError(self._error_message(e))
redis.exceptions.ConnectionError: Error 10060 connecting to 10.16.234.175:6379. A connection attempt failed because the connected party did not properly respond after a period of time, or established connection failed because connected host has failed to respond.
Traceback (most recent call last):
  File "C:\anaconda3\envs\RLV\lib\site-packages\redis\connection.py", line 550, in connect
    sock = self._connect()
  File "C:\anaconda3\envs\RLV\lib\site-packages\redis\connection.py", line 607, in _connect
    raise err
  File "C:\anaconda3\envs\RLV\lib\site-packages\redis\connection.py", line 595, in _connect
    sock.connect(socket_address)
TimeoutError: [WinError 10060] A connection attempt failed because the connected party did not properly respond after a period of time, or established connection failed because connected host has failed to respond

During handling of the above exception, another exception occurred:

Traceback (most recent call last):
  File "C:\anaconda3\envs\RLV\lib\site-packages\ray\reporter.py", line 234, in run
    self.perform_iteration()
  File "C:\anaconda3\envs\RLV\lib\site-packages\ray\reporter.py", line 219, in perform_iteration
    jsonify_asdict(stats),
  File "C:\anaconda3\envs\RLV\lib\site-packages\redis\client.py", line 3052, in publish
    return self.execute_command('PUBLISH', channel, message)
  File "C:\anaconda3\envs\RLV\lib\site-packages\redis\client.py", line 881, in execute_command
    conn = self.connection or pool.get_connection(command_name, **options)
  File "C:\anaconda3\envs\RLV\lib\site-packages\redis\connection.py", line 1178, in get_connection
    connection.connect()
  File "C:\anaconda3\envs\RLV\lib\site-packages\redis\connection.py", line 555, in connect
    raise ConnectionError(self._error_message(e))
redis.exceptions.ConnectionError: Error 10060 connecting to 10.16.234.175:6379. A connection attempt failed because the connected party did not properly respond after a period of time, or established connection failed because connected host has failed to respond.
Traceback (most recent call last):
  File "C:\anaconda3\envs\RLV\lib\site-packages\redis\connection.py", line 550, in connect
    sock = self._connect()
  File "C:\anaconda3\envs\RLV\lib\site-packages\redis\connection.py", line 607, in _connect
    raise err
  File "C:\anaconda3\envs\RLV\lib\site-packages\redis\connection.py", line 595, in _connect
    sock.connect(socket_address)
TimeoutError: [WinError 10060] A connection attempt failed because the connected party did not properly respond after a period of time, or established connection failed because connected host has failed to respond

During handling of the above exception, another exception occurred:

Traceback (most recent call last):
  File "C:\anaconda3\envs\RLV\lib\site-packages\ray\reporter.py", line 234, in run
    self.perform_iteration()
  File "C:\anaconda3\envs\RLV\lib\site-packages\ray\reporter.py", line 219, in perform_iteration
    jsonify_asdict(stats),
  File "C:\anaconda3\envs\RLV\lib\site-packages\redis\client.py", line 3052, in publish
    return self.execute_command('PUBLISH', channel, message)
  File "C:\anaconda3\envs\RLV\lib\site-packages\redis\client.py", line 881, in execute_command
    conn = self.connection or pool.get_connection(command_name, **options)
  File "C:\anaconda3\envs\RLV\lib\site-packages\redis\connection.py", line 1178, in get_connection
    connection.connect()
  File "C:\anaconda3\envs\RLV\lib\site-packages\redis\connection.py", line 555, in connect
    raise ConnectionError(self._error_message(e))
redis.exceptions.ConnectionError: Error 10060 connecting to 10.16.234.175:6379. A connection attempt failed because the connected party did not properly respond after a period of time, or established connection failed because connected host has failed to respond.
Traceback (most recent call last):
  File "C:\anaconda3\envs\RLV\lib\site-packages\redis\connection.py", line 550, in connect
    sock = self._connect()
  File "C:\anaconda3\envs\RLV\lib\site-packages\redis\connection.py", line 607, in _connect
    raise err
  File "C:\anaconda3\envs\RLV\lib\site-packages\redis\connection.py", line 595, in _connect
    sock.connect(socket_address)
TimeoutError: [WinError 10060] A connection attempt failed because the connected party did not properly respond after a period of time, or established connection failed because connected host has failed to respond

During handling of the above exception, another exception occurred:

Traceback (most recent call last):
  File "C:\anaconda3\envs\RLV\lib\site-packages\ray\reporter.py", line 234, in run
    self.perform_iteration()
  File "C:\anaconda3\envs\RLV\lib\site-packages\ray\reporter.py", line 219, in perform_iteration
    jsonify_asdict(stats),
  File "C:\anaconda3\envs\RLV\lib\site-packages\redis\client.py", line 3052, in publish
    return self.execute_command('PUBLISH', channel, message)
  File "C:\anaconda3\envs\RLV\lib\site-packages\redis\client.py", line 881, in execute_command
    conn = self.connection or pool.get_connection(command_name, **options)
  File "C:\anaconda3\envs\RLV\lib\site-packages\redis\connection.py", line 1178, in get_connection
    connection.connect()
  File "C:\anaconda3\envs\RLV\lib\site-packages\redis\connection.py", line 555, in connect
    raise ConnectionError(self._error_message(e))
redis.exceptions.ConnectionError: Error 10060 connecting to 10.16.234.175:6379. A connection attempt failed because the connected party did not properly respond after a period of time, or established connection failed because connected host has failed to respond.
Traceback (most recent call last):
  File "C:\anaconda3\envs\RLV\lib\site-packages\redis\connection.py", line 550, in connect
    sock = self._connect()
  File "C:\anaconda3\envs\RLV\lib\site-packages\redis\connection.py", line 607, in _connect
    raise err
  File "C:\anaconda3\envs\RLV\lib\site-packages\redis\connection.py", line 595, in _connect
    sock.connect(socket_address)
TimeoutError: [WinError 10060] A connection attempt failed because the connected party did not properly respond after a period of time, or established connection failed because connected host has failed to respond

During handling of the above exception, another exception occurred:

Traceback (most recent call last):
  File "C:\anaconda3\envs\RLV\lib\site-packages\ray\reporter.py", line 234, in run
    self.perform_iteration()
  File "C:\anaconda3\envs\RLV\lib\site-packages\ray\reporter.py", line 219, in perform_iteration
    jsonify_asdict(stats),
  File "C:\anaconda3\envs\RLV\lib\site-packages\redis\client.py", line 3052, in publish
    return self.execute_command('PUBLISH', channel, message)
  File "C:\anaconda3\envs\RLV\lib\site-packages\redis\client.py", line 881, in execute_command
    conn = self.connection or pool.get_connection(command_name, **options)
  File "C:\anaconda3\envs\RLV\lib\site-packages\redis\connection.py", line 1178, in get_connection
    connection.connect()
  File "C:\anaconda3\envs\RLV\lib\site-packages\redis\connection.py", line 555, in connect
    raise ConnectionError(self._error_message(e))
redis.exceptions.ConnectionError: Error 10060 connecting to 10.16.234.175:6379. A connection attempt failed because the connected party did not properly respond after a period of time, or established connection failed because connected host has failed to respond.
Traceback (most recent call last):
  File "C:\anaconda3\envs\RLV\lib\site-packages\redis\connection.py", line 550, in connect
    sock = self._connect()
  File "C:\anaconda3\envs\RLV\lib\site-packages\redis\connection.py", line 607, in _connect
    raise err
  File "C:\anaconda3\envs\RLV\lib\site-packages\redis\connection.py", line 595, in _connect
    sock.connect(socket_address)
TimeoutError: [WinError 10060] A connection attempt failed because the connected party did not properly respond after a period of time, or established connection failed because connected host has failed to respond

During handling of the above exception, another exception occurred:

Traceback (most recent call last):
  File "C:\anaconda3\envs\RLV\lib\site-packages\ray\reporter.py", line 234, in run
    self.perform_iteration()
  File "C:\anaconda3\envs\RLV\lib\site-packages\ray\reporter.py", line 219, in perform_iteration
    jsonify_asdict(stats),
  File "C:\anaconda3\envs\RLV\lib\site-packages\redis\client.py", line 3052, in publish
    return self.execute_command('PUBLISH', channel, message)
  File "C:\anaconda3\envs\RLV\lib\site-packages\redis\client.py", line 881, in execute_command
    conn = self.connection or pool.get_connection(command_name, **options)
  File "C:\anaconda3\envs\RLV\lib\site-packages\redis\connection.py", line 1178, in get_connection
    connection.connect()
  File "C:\anaconda3\envs\RLV\lib\site-packages\redis\connection.py", line 555, in connect
    raise ConnectionError(self._error_message(e))
redis.exceptions.ConnectionError: Error 10060 connecting to 10.16.234.175:6379. A connection attempt failed because the connected party did not properly respond after a period of time, or established connection failed because connected host has failed to respond.
Traceback (most recent call last):
  File "C:\anaconda3\envs\RLV\lib\site-packages\redis\connection.py", line 550, in connect
    sock = self._connect()
  File "C:\anaconda3\envs\RLV\lib\site-packages\redis\connection.py", line 607, in _connect
    raise err
  File "C:\anaconda3\envs\RLV\lib\site-packages\redis\connection.py", line 595, in _connect
    sock.connect(socket_address)
TimeoutError: [WinError 10060] A connection attempt failed because the connected party did not properly respond after a period of time, or established connection failed because connected host has failed to respond

During handling of the above exception, another exception occurred:

Traceback (most recent call last):
  File "C:\anaconda3\envs\RLV\lib\site-packages\ray\reporter.py", line 234, in run
    self.perform_iteration()
  File "C:\anaconda3\envs\RLV\lib\site-packages\ray\reporter.py", line 219, in perform_iteration
    jsonify_asdict(stats),
  File "C:\anaconda3\envs\RLV\lib\site-packages\redis\client.py", line 3052, in publish
    return self.execute_command('PUBLISH', channel, message)
  File "C:\anaconda3\envs\RLV\lib\site-packages\redis\client.py", line 881, in execute_command
    conn = self.connection or pool.get_connection(command_name, **options)
  File "C:\anaconda3\envs\RLV\lib\site-packages\redis\connection.py", line 1178, in get_connection
    connection.connect()
  File "C:\anaconda3\envs\RLV\lib\site-packages\redis\connection.py", line 555, in connect
    raise ConnectionError(self._error_message(e))
redis.exceptions.ConnectionError: Error 10060 connecting to 10.16.234.175:6379. A connection attempt failed because the connected party did not properly respond after a period of time, or established connection failed because connected host has failed to respond.
Traceback (most recent call last):
  File "C:\anaconda3\envs\RLV\lib\site-packages\redis\connection.py", line 550, in connect
    sock = self._connect()
  File "C:\anaconda3\envs\RLV\lib\site-packages\redis\connection.py", line 607, in _connect
    raise err
  File "C:\anaconda3\envs\RLV\lib\site-packages\redis\connection.py", line 595, in _connect
    sock.connect(socket_address)
TimeoutError: [WinError 10060] A connection attempt failed because the connected party did not properly respond after a period of time, or established connection failed because connected host has failed to respond

During handling of the above exception, another exception occurred:

Traceback (most recent call last):
  File "C:\anaconda3\envs\RLV\lib\site-packages\ray\reporter.py", line 234, in run
    self.perform_iteration()
  File "C:\anaconda3\envs\RLV\lib\site-packages\ray\reporter.py", line 219, in perform_iteration
    jsonify_asdict(stats),
  File "C:\anaconda3\envs\RLV\lib\site-packages\redis\client.py", line 3052, in publish
    return self.execute_command('PUBLISH', channel, message)
  File "C:\anaconda3\envs\RLV\lib\site-packages\redis\client.py", line 881, in execute_command
    conn = self.connection or pool.get_connection(command_name, **options)
  File "C:\anaconda3\envs\RLV\lib\site-packages\redis\connection.py", line 1178, in get_connection
    connection.connect()
  File "C:\anaconda3\envs\RLV\lib\site-packages\redis\connection.py", line 555, in connect
    raise ConnectionError(self._error_message(e))
redis.exceptions.ConnectionError: Error 10060 connecting to 10.16.234.175:6379. A connection attempt failed because the connected party did not properly respond after a period of time, or established connection failed because connected host has failed to respond.
Traceback (most recent call last):
  File "C:\anaconda3\envs\RLV\lib\site-packages\redis\connection.py", line 550, in connect
    sock = self._connect()
  File "C:\anaconda3\envs\RLV\lib\site-packages\redis\connection.py", line 607, in _connect
    raise err
  File "C:\anaconda3\envs\RLV\lib\site-packages\redis\connection.py", line 595, in _connect
    sock.connect(socket_address)
TimeoutError: [WinError 10060] A connection attempt failed because the connected party did not properly respond after a period of time, or established connection failed because connected host has failed to respond

During handling of the above exception, another exception occurred:

Traceback (most recent call last):
  File "C:\anaconda3\envs\RLV\lib\site-packages\ray\reporter.py", line 234, in run
    self.perform_iteration()
  File "C:\anaconda3\envs\RLV\lib\site-packages\ray\reporter.py", line 219, in perform_iteration
    jsonify_asdict(stats),
  File "C:\anaconda3\envs\RLV\lib\site-packages\redis\client.py", line 3052, in publish
    return self.execute_command('PUBLISH', channel, message)
  File "C:\anaconda3\envs\RLV\lib\site-packages\redis\client.py", line 881, in execute_command
    conn = self.connection or pool.get_connection(command_name, **options)
  File "C:\anaconda3\envs\RLV\lib\site-packages\redis\connection.py", line 1178, in get_connection
    connection.connect()
  File "C:\anaconda3\envs\RLV\lib\site-packages\redis\connection.py", line 555, in connect
    raise ConnectionError(self._error_message(e))
redis.exceptions.ConnectionError: Error 10060 connecting to 10.16.234.175:6379. A connection attempt failed because the connected party did not properly respond after a period of time, or established connection failed because connected host has failed to respond.
Traceback (most recent call last):
  File "C:\anaconda3\envs\RLV\lib\site-packages\redis\connection.py", line 550, in connect
    sock = self._connect()
  File "C:\anaconda3\envs\RLV\lib\site-packages\redis\connection.py", line 607, in _connect
    raise err
  File "C:\anaconda3\envs\RLV\lib\site-packages\redis\connection.py", line 595, in _connect
    sock.connect(socket_address)
TimeoutError: [WinError 10060] A connection attempt failed because the connected party did not properly respond after a period of time, or established connection failed because connected host has failed to respond

During handling of the above exception, another exception occurred:

Traceback (most recent call last):
  File "C:\anaconda3\envs\RLV\lib\site-packages\ray\reporter.py", line 234, in run
    self.perform_iteration()
  File "C:\anaconda3\envs\RLV\lib\site-packages\ray\reporter.py", line 219, in perform_iteration
    jsonify_asdict(stats),
  File "C:\anaconda3\envs\RLV\lib\site-packages\redis\client.py", line 3052, in publish
    return self.execute_command('PUBLISH', channel, message)
  File "C:\anaconda3\envs\RLV\lib\site-packages\redis\client.py", line 881, in execute_command
    conn = self.connection or pool.get_connection(command_name, **options)
  File "C:\anaconda3\envs\RLV\lib\site-packages\redis\connection.py", line 1178, in get_connection
    connection.connect()
  File "C:\anaconda3\envs\RLV\lib\site-packages\redis\connection.py", line 555, in connect
    raise ConnectionError(self._error_message(e))
redis.exceptions.ConnectionError: Error 10060 connecting to 10.16.234.175:6379. A connection attempt failed because the connected party did not properly respond after a period of time, or established connection failed because connected host has failed to respond.
Traceback (most recent call last):
  File "C:\anaconda3\envs\RLV\lib\site-packages\redis\connection.py", line 550, in connect
    sock = self._connect()
  File "C:\anaconda3\envs\RLV\lib\site-packages\redis\connection.py", line 607, in _connect
    raise err
  File "C:\anaconda3\envs\RLV\lib\site-packages\redis\connection.py", line 595, in _connect
    sock.connect(socket_address)
TimeoutError: [WinError 10060] A connection attempt failed because the connected party did not properly respond after a period of time, or established connection failed because connected host has failed to respond

During handling of the above exception, another exception occurred:

Traceback (most recent call last):
  File "C:\anaconda3\envs\RLV\lib\site-packages\ray\reporter.py", line 234, in run
    self.perform_iteration()
  File "C:\anaconda3\envs\RLV\lib\site-packages\ray\reporter.py", line 219, in perform_iteration
    jsonify_asdict(stats),
  File "C:\anaconda3\envs\RLV\lib\site-packages\redis\client.py", line 3052, in publish
    return self.execute_command('PUBLISH', channel, message)
  File "C:\anaconda3\envs\RLV\lib\site-packages\redis\client.py", line 881, in execute_command
    conn = self.connection or pool.get_connection(command_name, **options)
  File "C:\anaconda3\envs\RLV\lib\site-packages\redis\connection.py", line 1178, in get_connection
    connection.connect()
  File "C:\anaconda3\envs\RLV\lib\site-packages\redis\connection.py", line 555, in connect
    raise ConnectionError(self._error_message(e))
redis.exceptions.ConnectionError: Error 10060 connecting to 10.16.234.175:6379. A connection attempt failed because the connected party did not properly respond after a period of time, or established connection failed because connected host has failed to respond.
Traceback (most recent call last):
  File "C:\anaconda3\envs\RLV\lib\site-packages\redis\connection.py", line 550, in connect
    sock = self._connect()
  File "C:\anaconda3\envs\RLV\lib\site-packages\redis\connection.py", line 607, in _connect
    raise err
  File "C:\anaconda3\envs\RLV\lib\site-packages\redis\connection.py", line 595, in _connect
    sock.connect(socket_address)
TimeoutError: [WinError 10060] A connection attempt failed because the connected party did not properly respond after a period of time, or established connection failed because connected host has failed to respond

During handling of the above exception, another exception occurred:

Traceback (most recent call last):
  File "C:\anaconda3\envs\RLV\lib\site-packages\ray\reporter.py", line 234, in run
    self.perform_iteration()
  File "C:\anaconda3\envs\RLV\lib\site-packages\ray\reporter.py", line 219, in perform_iteration
    jsonify_asdict(stats),
  File "C:\anaconda3\envs\RLV\lib\site-packages\redis\client.py", line 3052, in publish
    return self.execute_command('PUBLISH', channel, message)
  File "C:\anaconda3\envs\RLV\lib\site-packages\redis\client.py", line 881, in execute_command
    conn = self.connection or pool.get_connection(command_name, **options)
  File "C:\anaconda3\envs\RLV\lib\site-packages\redis\connection.py", line 1178, in get_connection
    connection.connect()
  File "C:\anaconda3\envs\RLV\lib\site-packages\redis\connection.py", line 555, in connect
    raise ConnectionError(self._error_message(e))
redis.exceptions.ConnectionError: Error 10060 connecting to 10.16.234.175:6379. A connection attempt failed because the connected party did not properly respond after a period of time, or established connection failed because connected host has failed to respond.
Traceback (most recent call last):
  File "C:\anaconda3\envs\RLV\lib\site-packages\redis\connection.py", line 550, in connect
    sock = self._connect()
  File "C:\anaconda3\envs\RLV\lib\site-packages\redis\connection.py", line 607, in _connect
    raise err
  File "C:\anaconda3\envs\RLV\lib\site-packages\redis\connection.py", line 595, in _connect
    sock.connect(socket_address)
TimeoutError: [WinError 10060] A connection attempt failed because the connected party did not properly respond after a period of time, or established connection failed because connected host has failed to respond

During handling of the above exception, another exception occurred:

Traceback (most recent call last):
  File "C:\anaconda3\envs\RLV\lib\site-packages\ray\reporter.py", line 234, in run
    self.perform_iteration()
  File "C:\anaconda3\envs\RLV\lib\site-packages\ray\reporter.py", line 219, in perform_iteration
    jsonify_asdict(stats),
  File "C:\anaconda3\envs\RLV\lib\site-packages\redis\client.py", line 3052, in publish
    return self.execute_command('PUBLISH', channel, message)
  File "C:\anaconda3\envs\RLV\lib\site-packages\redis\client.py", line 881, in execute_command
    conn = self.connection or pool.get_connection(command_name, **options)
  File "C:\anaconda3\envs\RLV\lib\site-packages\redis\connection.py", line 1178, in get_connection
    connection.connect()
  File "C:\anaconda3\envs\RLV\lib\site-packages\redis\connection.py", line 555, in connect
    raise ConnectionError(self._error_message(e))
redis.exceptions.ConnectionError: Error 10060 connecting to 10.16.234.175:6379. A connection attempt failed because the connected party did not properly respond after a period of time, or established connection failed because connected host has failed to respond.
Traceback (most recent call last):
  File "C:\anaconda3\envs\RLV\lib\site-packages\redis\connection.py", line 550, in connect
    sock = self._connect()
  File "C:\anaconda3\envs\RLV\lib\site-packages\redis\connection.py", line 607, in _connect
    raise err
  File "C:\anaconda3\envs\RLV\lib\site-packages\redis\connection.py", line 595, in _connect
    sock.connect(socket_address)
TimeoutError: [WinError 10060] A connection attempt failed because the connected party did not properly respond after a period of time, or established connection failed because connected host has failed to respond

During handling of the above exception, another exception occurred:

Traceback (most recent call last):
  File "C:\anaconda3\envs\RLV\lib\site-packages\ray\reporter.py", line 234, in run
    self.perform_iteration()
  File "C:\anaconda3\envs\RLV\lib\site-packages\ray\reporter.py", line 219, in perform_iteration
    jsonify_asdict(stats),
  File "C:\anaconda3\envs\RLV\lib\site-packages\redis\client.py", line 3052, in publish
    return self.execute_command('PUBLISH', channel, message)
  File "C:\anaconda3\envs\RLV\lib\site-packages\redis\client.py", line 881, in execute_command
    conn = self.connection or pool.get_connection(command_name, **options)
  File "C:\anaconda3\envs\RLV\lib\site-packages\redis\connection.py", line 1178, in get_connection
    connection.connect()
  File "C:\anaconda3\envs\RLV\lib\site-packages\redis\connection.py", line 555, in connect
    raise ConnectionError(self._error_message(e))
redis.exceptions.ConnectionError: Error 10060 connecting to 10.16.234.175:6379. A connection attempt failed because the connected party did not properly respond after a period of time, or established connection failed because connected host has failed to respond.
Traceback (most recent call last):
  File "C:\anaconda3\envs\RLV\lib\site-packages\redis\connection.py", line 550, in connect
    sock = self._connect()
  File "C:\anaconda3\envs\RLV\lib\site-packages\redis\connection.py", line 607, in _connect
    raise err
  File "C:\anaconda3\envs\RLV\lib\site-packages\redis\connection.py", line 595, in _connect
    sock.connect(socket_address)
TimeoutError: [WinError 10060] A connection attempt failed because the connected party did not properly respond after a period of time, or established connection failed because connected host has failed to respond

During handling of the above exception, another exception occurred:

Traceback (most recent call last):
  File "C:\anaconda3\envs\RLV\lib\site-packages\ray\reporter.py", line 234, in run
    self.perform_iteration()
  File "C:\anaconda3\envs\RLV\lib\site-packages\ray\reporter.py", line 219, in perform_iteration
    jsonify_asdict(stats),
  File "C:\anaconda3\envs\RLV\lib\site-packages\redis\client.py", line 3052, in publish
    return self.execute_command('PUBLISH', channel, message)
  File "C:\anaconda3\envs\RLV\lib\site-packages\redis\client.py", line 881, in execute_command
    conn = self.connection or pool.get_connection(command_name, **options)
  File "C:\anaconda3\envs\RLV\lib\site-packages\redis\connection.py", line 1178, in get_connection
    connection.connect()
  File "C:\anaconda3\envs\RLV\lib\site-packages\redis\connection.py", line 555, in connect
    raise ConnectionError(self._error_message(e))
redis.exceptions.ConnectionError: Error 10060 connecting to 10.16.234.175:6379. A connection attempt failed because the connected party did not properly respond after a period of time, or established connection failed because connected host has failed to respond.
Traceback (most recent call last):
  File "C:\anaconda3\envs\RLV\lib\site-packages\redis\connection.py", line 550, in connect
    sock = self._connect()
  File "C:\anaconda3\envs\RLV\lib\site-packages\redis\connection.py", line 607, in _connect
    raise err
  File "C:\anaconda3\envs\RLV\lib\site-packages\redis\connection.py", line 595, in _connect
    sock.connect(socket_address)
TimeoutError: [WinError 10060] A connection attempt failed because the connected party did not properly respond after a period of time, or established connection failed because connected host has failed to respond

During handling of the above exception, another exception occurred:

Traceback (most recent call last):
  File "C:\anaconda3\envs\RLV\lib\site-packages\ray\reporter.py", line 234, in run
    self.perform_iteration()
  File "C:\anaconda3\envs\RLV\lib\site-packages\ray\reporter.py", line 219, in perform_iteration
    jsonify_asdict(stats),
  File "C:\anaconda3\envs\RLV\lib\site-packages\redis\client.py", line 3052, in publish
    return self.execute_command('PUBLISH', channel, message)
  File "C:\anaconda3\envs\RLV\lib\site-packages\redis\client.py", line 881, in execute_command
    conn = self.connection or pool.get_connection(command_name, **options)
  File "C:\anaconda3\envs\RLV\lib\site-packages\redis\connection.py", line 1178, in get_connection
    connection.connect()
  File "C:\anaconda3\envs\RLV\lib\site-packages\redis\connection.py", line 555, in connect
    raise ConnectionError(self._error_message(e))
redis.exceptions.ConnectionError: Error 10060 connecting to 10.16.234.175:6379. A connection attempt failed because the connected party did not properly respond after a period of time, or established connection failed because connected host has failed to respond.
Traceback (most recent call last):
  File "C:\anaconda3\envs\RLV\lib\site-packages\redis\connection.py", line 550, in connect
    sock = self._connect()
  File "C:\anaconda3\envs\RLV\lib\site-packages\redis\connection.py", line 607, in _connect
    raise err
  File "C:\anaconda3\envs\RLV\lib\site-packages\redis\connection.py", line 595, in _connect
    sock.connect(socket_address)
TimeoutError: [WinError 10060] A connection attempt failed because the connected party did not properly respond after a period of time, or established connection failed because connected host has failed to respond

During handling of the above exception, another exception occurred:

Traceback (most recent call last):
  File "C:\anaconda3\envs\RLV\lib\site-packages\ray\reporter.py", line 234, in run
    self.perform_iteration()
  File "C:\anaconda3\envs\RLV\lib\site-packages\ray\reporter.py", line 219, in perform_iteration
    jsonify_asdict(stats),
  File "C:\anaconda3\envs\RLV\lib\site-packages\redis\client.py", line 3052, in publish
    return self.execute_command('PUBLISH', channel, message)
  File "C:\anaconda3\envs\RLV\lib\site-packages\redis\client.py", line 881, in execute_command
    conn = self.connection or pool.get_connection(command_name, **options)
  File "C:\anaconda3\envs\RLV\lib\site-packages\redis\connection.py", line 1178, in get_connection
    connection.connect()
  File "C:\anaconda3\envs\RLV\lib\site-packages\redis\connection.py", line 555, in connect
    raise ConnectionError(self._error_message(e))
redis.exceptions.ConnectionError: Error 10060 connecting to 10.16.234.175:6379. A connection attempt failed because the connected party did not properly respond after a period of time, or established connection failed because connected host has failed to respond.
Traceback (most recent call last):
  File "C:\anaconda3\envs\RLV\lib\site-packages\redis\connection.py", line 550, in connect
    sock = self._connect()
  File "C:\anaconda3\envs\RLV\lib\site-packages\redis\connection.py", line 607, in _connect
    raise err
  File "C:\anaconda3\envs\RLV\lib\site-packages\redis\connection.py", line 595, in _connect
    sock.connect(socket_address)
TimeoutError: [WinError 10060] A connection attempt failed because the connected party did not properly respond after a period of time, or established connection failed because connected host has failed to respond

During handling of the above exception, another exception occurred:

Traceback (most recent call last):
  File "C:\anaconda3\envs\RLV\lib\site-packages\ray\reporter.py", line 234, in run
    self.perform_iteration()
  File "C:\anaconda3\envs\RLV\lib\site-packages\ray\reporter.py", line 219, in perform_iteration
    jsonify_asdict(stats),
  File "C:\anaconda3\envs\RLV\lib\site-packages\redis\client.py", line 3052, in publish
    return self.execute_command('PUBLISH', channel, message)
  File "C:\anaconda3\envs\RLV\lib\site-packages\redis\client.py", line 881, in execute_command
    conn = self.connection or pool.get_connection(command_name, **options)
  File "C:\anaconda3\envs\RLV\lib\site-packages\redis\connection.py", line 1178, in get_connection
    connection.connect()
  File "C:\anaconda3\envs\RLV\lib\site-packages\redis\connection.py", line 555, in connect
    raise ConnectionError(self._error_message(e))
redis.exceptions.ConnectionError: Error 10060 connecting to 10.16.234.175:6379. A connection attempt failed because the connected party did not properly respond after a period of time, or established connection failed because connected host has failed to respond.
Traceback (most recent call last):
  File "C:\anaconda3\envs\RLV\lib\site-packages\redis\connection.py", line 550, in connect
    sock = self._connect()
  File "C:\anaconda3\envs\RLV\lib\site-packages\redis\connection.py", line 607, in _connect
    raise err
  File "C:\anaconda3\envs\RLV\lib\site-packages\redis\connection.py", line 595, in _connect
    sock.connect(socket_address)
TimeoutError: [WinError 10060] A connection attempt failed because the connected party did not properly respond after a period of time, or established connection failed because connected host has failed to respond

During handling of the above exception, another exception occurred:

Traceback (most recent call last):
  File "C:\anaconda3\envs\RLV\lib\site-packages\ray\reporter.py", line 234, in run
    self.perform_iteration()
  File "C:\anaconda3\envs\RLV\lib\site-packages\ray\reporter.py", line 219, in perform_iteration
    jsonify_asdict(stats),
  File "C:\anaconda3\envs\RLV\lib\site-packages\redis\client.py", line 3052, in publish
    return self.execute_command('PUBLISH', channel, message)
  File "C:\anaconda3\envs\RLV\lib\site-packages\redis\client.py", line 881, in execute_command
    conn = self.connection or pool.get_connection(command_name, **options)
  File "C:\anaconda3\envs\RLV\lib\site-packages\redis\connection.py", line 1178, in get_connection
    connection.connect()
  File "C:\anaconda3\envs\RLV\lib\site-packages\redis\connection.py", line 555, in connect
    raise ConnectionError(self._error_message(e))
redis.exceptions.ConnectionError: Error 10060 connecting to 10.16.234.175:6379. A connection attempt failed because the connected party did not properly respond after a period of time, or established connection failed because connected host has failed to respond.
Traceback (most recent call last):
  File "C:\anaconda3\envs\RLV\lib\site-packages\redis\connection.py", line 550, in connect
    sock = self._connect()
  File "C:\anaconda3\envs\RLV\lib\site-packages\redis\connection.py", line 607, in _connect
    raise err
  File "C:\anaconda3\envs\RLV\lib\site-packages\redis\connection.py", line 595, in _connect
    sock.connect(socket_address)
TimeoutError: [WinError 10060] A connection attempt failed because the connected party did not properly respond after a period of time, or established connection failed because connected host has failed to respond

During handling of the above exception, another exception occurred:

Traceback (most recent call last):
  File "C:\anaconda3\envs\RLV\lib\site-packages\ray\reporter.py", line 234, in run
    self.perform_iteration()
  File "C:\anaconda3\envs\RLV\lib\site-packages\ray\reporter.py", line 219, in perform_iteration
    jsonify_asdict(stats),
  File "C:\anaconda3\envs\RLV\lib\site-packages\redis\client.py", line 3052, in publish
    return self.execute_command('PUBLISH', channel, message)
  File "C:\anaconda3\envs\RLV\lib\site-packages\redis\client.py", line 881, in execute_command
    conn = self.connection or pool.get_connection(command_name, **options)
  File "C:\anaconda3\envs\RLV\lib\site-packages\redis\connection.py", line 1178, in get_connection
    connection.connect()
  File "C:\anaconda3\envs\RLV\lib\site-packages\redis\connection.py", line 555, in connect
    raise ConnectionError(self._error_message(e))
redis.exceptions.ConnectionError: Error 10060 connecting to 10.16.234.175:6379. A connection attempt failed because the connected party did not properly respond after a period of time, or established connection failed because connected host has failed to respond.
Traceback (most recent call last):
  File "C:\anaconda3\envs\RLV\lib\site-packages\redis\connection.py", line 550, in connect
    sock = self._connect()
  File "C:\anaconda3\envs\RLV\lib\site-packages\redis\connection.py", line 607, in _connect
    raise err
  File "C:\anaconda3\envs\RLV\lib\site-packages\redis\connection.py", line 595, in _connect
    sock.connect(socket_address)
TimeoutError: [WinError 10060] A connection attempt failed because the connected party did not properly respond after a period of time, or established connection failed because connected host has failed to respond

During handling of the above exception, another exception occurred:

Traceback (most recent call last):
  File "C:\anaconda3\envs\RLV\lib\site-packages\ray\reporter.py", line 234, in run
    self.perform_iteration()
  File "C:\anaconda3\envs\RLV\lib\site-packages\ray\reporter.py", line 219, in perform_iteration
    jsonify_asdict(stats),
  File "C:\anaconda3\envs\RLV\lib\site-packages\redis\client.py", line 3052, in publish
    return self.execute_command('PUBLISH', channel, message)
  File "C:\anaconda3\envs\RLV\lib\site-packages\redis\client.py", line 881, in execute_command
    conn = self.connection or pool.get_connection(command_name, **options)
  File "C:\anaconda3\envs\RLV\lib\site-packages\redis\connection.py", line 1178, in get_connection
    connection.connect()
  File "C:\anaconda3\envs\RLV\lib\site-packages\redis\connection.py", line 555, in connect
    raise ConnectionError(self._error_message(e))
redis.exceptions.ConnectionError: Error 10060 connecting to 10.16.234.175:6379. A connection attempt failed because the connected party did not properly respond after a period of time, or established connection failed because connected host has failed to respond.
Traceback (most recent call last):
  File "C:\anaconda3\envs\RLV\lib\site-packages\redis\connection.py", line 550, in connect
    sock = self._connect()
  File "C:\anaconda3\envs\RLV\lib\site-packages\redis\connection.py", line 607, in _connect
    raise err
  File "C:\anaconda3\envs\RLV\lib\site-packages\redis\connection.py", line 595, in _connect
    sock.connect(socket_address)
TimeoutError: [WinError 10060] A connection attempt failed because the connected party did not properly respond after a period of time, or established connection failed because connected host has failed to respond

During handling of the above exception, another exception occurred:

Traceback (most recent call last):
  File "C:\anaconda3\envs\RLV\lib\site-packages\ray\reporter.py", line 234, in run
    self.perform_iteration()
  File "C:\anaconda3\envs\RLV\lib\site-packages\ray\reporter.py", line 219, in perform_iteration
    jsonify_asdict(stats),
  File "C:\anaconda3\envs\RLV\lib\site-packages\redis\client.py", line 3052, in publish
    return self.execute_command('PUBLISH', channel, message)
  File "C:\anaconda3\envs\RLV\lib\site-packages\redis\client.py", line 881, in execute_command
    conn = self.connection or pool.get_connection(command_name, **options)
  File "C:\anaconda3\envs\RLV\lib\site-packages\redis\connection.py", line 1178, in get_connection
    connection.connect()
  File "C:\anaconda3\envs\RLV\lib\site-packages\redis\connection.py", line 555, in connect
    raise ConnectionError(self._error_message(e))
redis.exceptions.ConnectionError: Error 10060 connecting to 10.16.234.175:6379. A connection attempt failed because the connected party did not properly respond after a period of time, or established connection failed because connected host has failed to respond.
Traceback (most recent call last):
  File "C:\anaconda3\envs\RLV\lib\site-packages\redis\connection.py", line 550, in connect
    sock = self._connect()
  File "C:\anaconda3\envs\RLV\lib\site-packages\redis\connection.py", line 607, in _connect
    raise err
  File "C:\anaconda3\envs\RLV\lib\site-packages\redis\connection.py", line 595, in _connect
    sock.connect(socket_address)
TimeoutError: [WinError 10060] A connection attempt failed because the connected party did not properly respond after a period of time, or established connection failed because connected host has failed to respond

During handling of the above exception, another exception occurred:

Traceback (most recent call last):
  File "C:\anaconda3\envs\RLV\lib\site-packages\ray\reporter.py", line 234, in run
    self.perform_iteration()
  File "C:\anaconda3\envs\RLV\lib\site-packages\ray\reporter.py", line 219, in perform_iteration
    jsonify_asdict(stats),
  File "C:\anaconda3\envs\RLV\lib\site-packages\redis\client.py", line 3052, in publish
    return self.execute_command('PUBLISH', channel, message)
  File "C:\anaconda3\envs\RLV\lib\site-packages\redis\client.py", line 881, in execute_command
    conn = self.connection or pool.get_connection(command_name, **options)
  File "C:\anaconda3\envs\RLV\lib\site-packages\redis\connection.py", line 1178, in get_connection
    connection.connect()
  File "C:\anaconda3\envs\RLV\lib\site-packages\redis\connection.py", line 555, in connect
    raise ConnectionError(self._error_message(e))
redis.exceptions.ConnectionError: Error 10060 connecting to 10.16.234.175:6379. A connection attempt failed because the connected party did not properly respond after a period of time, or established connection failed because connected host has failed to respond.
Traceback (most recent call last):
  File "C:\anaconda3\envs\RLV\lib\site-packages\redis\connection.py", line 550, in connect
    sock = self._connect()
  File "C:\anaconda3\envs\RLV\lib\site-packages\redis\connection.py", line 607, in _connect
    raise err
  File "C:\anaconda3\envs\RLV\lib\site-packages\redis\connection.py", line 595, in _connect
    sock.connect(socket_address)
TimeoutError: [WinError 10060] A connection attempt failed because the connected party did not properly respond after a period of time, or established connection failed because connected host has failed to respond

During handling of the above exception, another exception occurred:

Traceback (most recent call last):
  File "C:\anaconda3\envs\RLV\lib\site-packages\ray\reporter.py", line 234, in run
    self.perform_iteration()
  File "C:\anaconda3\envs\RLV\lib\site-packages\ray\reporter.py", line 219, in perform_iteration
    jsonify_asdict(stats),
  File "C:\anaconda3\envs\RLV\lib\site-packages\redis\client.py", line 3052, in publish
    return self.execute_command('PUBLISH', channel, message)
  File "C:\anaconda3\envs\RLV\lib\site-packages\redis\client.py", line 881, in execute_command
    conn = self.connection or pool.get_connection(command_name, **options)
  File "C:\anaconda3\envs\RLV\lib\site-packages\redis\connection.py", line 1178, in get_connection
    connection.connect()
  File "C:\anaconda3\envs\RLV\lib\site-packages\redis\connection.py", line 555, in connect
    raise ConnectionError(self._error_message(e))
redis.exceptions.ConnectionError: Error 10060 connecting to 10.16.234.175:6379. A connection attempt failed because the connected party did not properly respond after a period of time, or established connection failed because connected host has failed to respond.
Traceback (most recent call last):
  File "C:\anaconda3\envs\RLV\lib\site-packages\redis\connection.py", line 550, in connect
    sock = self._connect()
  File "C:\anaconda3\envs\RLV\lib\site-packages\redis\connection.py", line 607, in _connect
    raise err
  File "C:\anaconda3\envs\RLV\lib\site-packages\redis\connection.py", line 595, in _connect
    sock.connect(socket_address)
TimeoutError: [WinError 10060] A connection attempt failed because the connected party did not properly respond after a period of time, or established connection failed because connected host has failed to respond

During handling of the above exception, another exception occurred:

Traceback (most recent call last):
  File "C:\anaconda3\envs\RLV\lib\site-packages\ray\reporter.py", line 234, in run
    self.perform_iteration()
  File "C:\anaconda3\envs\RLV\lib\site-packages\ray\reporter.py", line 219, in perform_iteration
    jsonify_asdict(stats),
  File "C:\anaconda3\envs\RLV\lib\site-packages\redis\client.py", line 3052, in publish
    return self.execute_command('PUBLISH', channel, message)
  File "C:\anaconda3\envs\RLV\lib\site-packages\redis\client.py", line 881, in execute_command
    conn = self.connection or pool.get_connection(command_name, **options)
  File "C:\anaconda3\envs\RLV\lib\site-packages\redis\connection.py", line 1178, in get_connection
    connection.connect()
  File "C:\anaconda3\envs\RLV\lib\site-packages\redis\connection.py", line 555, in connect
    raise ConnectionError(self._error_message(e))
redis.exceptions.ConnectionError: Error 10060 connecting to 10.16.234.175:6379. A connection attempt failed because the connected party did not properly respond after a period of time, or established connection failed because connected host has failed to respond.
Traceback (most recent call last):
  File "C:\anaconda3\envs\RLV\lib\site-packages\redis\connection.py", line 550, in connect
    sock = self._connect()
  File "C:\anaconda3\envs\RLV\lib\site-packages\redis\connection.py", line 607, in _connect
    raise err
  File "C:\anaconda3\envs\RLV\lib\site-packages\redis\connection.py", line 595, in _connect
    sock.connect(socket_address)
TimeoutError: [WinError 10060] A connection attempt failed because the connected party did not properly respond after a period of time, or established connection failed because connected host has failed to respond

During handling of the above exception, another exception occurred:

Traceback (most recent call last):
  File "C:\anaconda3\envs\RLV\lib\site-packages\ray\reporter.py", line 234, in run
    self.perform_iteration()
  File "C:\anaconda3\envs\RLV\lib\site-packages\ray\reporter.py", line 219, in perform_iteration
    jsonify_asdict(stats),
  File "C:\anaconda3\envs\RLV\lib\site-packages\redis\client.py", line 3052, in publish
    return self.execute_command('PUBLISH', channel, message)
  File "C:\anaconda3\envs\RLV\lib\site-packages\redis\client.py", line 881, in execute_command
    conn = self.connection or pool.get_connection(command_name, **options)
  File "C:\anaconda3\envs\RLV\lib\site-packages\redis\connection.py", line 1178, in get_connection
    connection.connect()
  File "C:\anaconda3\envs\RLV\lib\site-packages\redis\connection.py", line 555, in connect
    raise ConnectionError(self._error_message(e))
redis.exceptions.ConnectionError: Error 10060 connecting to 10.16.234.175:6379. A connection attempt failed because the connected party did not properly respond after a period of time, or established connection failed because connected host has failed to respond.
Traceback (most recent call last):
  File "C:\anaconda3\envs\RLV\lib\site-packages\redis\connection.py", line 550, in connect
    sock = self._connect()
  File "C:\anaconda3\envs\RLV\lib\site-packages\redis\connection.py", line 607, in _connect
    raise err
  File "C:\anaconda3\envs\RLV\lib\site-packages\redis\connection.py", line 595, in _connect
    sock.connect(socket_address)
TimeoutError: [WinError 10060] A connection attempt failed because the connected party did not properly respond after a period of time, or established connection failed because connected host has failed to respond

During handling of the above exception, another exception occurred:

Traceback (most recent call last):
  File "C:\anaconda3\envs\RLV\lib\site-packages\ray\reporter.py", line 234, in run
    self.perform_iteration()
  File "C:\anaconda3\envs\RLV\lib\site-packages\ray\reporter.py", line 219, in perform_iteration
    jsonify_asdict(stats),
  File "C:\anaconda3\envs\RLV\lib\site-packages\redis\client.py", line 3052, in publish
    return self.execute_command('PUBLISH', channel, message)
  File "C:\anaconda3\envs\RLV\lib\site-packages\redis\client.py", line 881, in execute_command
    conn = self.connection or pool.get_connection(command_name, **options)
  File "C:\anaconda3\envs\RLV\lib\site-packages\redis\connection.py", line 1178, in get_connection
    connection.connect()
  File "C:\anaconda3\envs\RLV\lib\site-packages\redis\connection.py", line 555, in connect
    raise ConnectionError(self._error_message(e))
redis.exceptions.ConnectionError: Error 10060 connecting to 10.16.234.175:6379. A connection attempt failed because the connected party did not properly respond after a period of time, or established connection failed because connected host has failed to respond.
Traceback (most recent call last):
  File "C:\anaconda3\envs\RLV\lib\site-packages\redis\connection.py", line 550, in connect
    sock = self._connect()
  File "C:\anaconda3\envs\RLV\lib\site-packages\redis\connection.py", line 607, in _connect
    raise err
  File "C:\anaconda3\envs\RLV\lib\site-packages\redis\connection.py", line 595, in _connect
    sock.connect(socket_address)
TimeoutError: [WinError 10060] A connection attempt failed because the connected party did not properly respond after a period of time, or established connection failed because connected host has failed to respond

During handling of the above exception, another exception occurred:

Traceback (most recent call last):
  File "C:\anaconda3\envs\RLV\lib\site-packages\ray\reporter.py", line 234, in run
    self.perform_iteration()
  File "C:\anaconda3\envs\RLV\lib\site-packages\ray\reporter.py", line 219, in perform_iteration
    jsonify_asdict(stats),
  File "C:\anaconda3\envs\RLV\lib\site-packages\redis\client.py", line 3052, in publish
    return self.execute_command('PUBLISH', channel, message)
  File "C:\anaconda3\envs\RLV\lib\site-packages\redis\client.py", line 881, in execute_command
    conn = self.connection or pool.get_connection(command_name, **options)
  File "C:\anaconda3\envs\RLV\lib\site-packages\redis\connection.py", line 1178, in get_connection
    connection.connect()
  File "C:\anaconda3\envs\RLV\lib\site-packages\redis\connection.py", line 555, in connect
    raise ConnectionError(self._error_message(e))
redis.exceptions.ConnectionError: Error 10060 connecting to 10.16.234.175:6379. A connection attempt failed because the connected party did not properly respond after a period of time, or established connection failed because connected host has failed to respond.
Traceback (most recent call last):
  File "C:\anaconda3\envs\RLV\lib\site-packages\redis\connection.py", line 550, in connect
    sock = self._connect()
  File "C:\anaconda3\envs\RLV\lib\site-packages\redis\connection.py", line 607, in _connect
    raise err
  File "C:\anaconda3\envs\RLV\lib\site-packages\redis\connection.py", line 595, in _connect
    sock.connect(socket_address)
TimeoutError: [WinError 10060] A connection attempt failed because the connected party did not properly respond after a period of time, or established connection failed because connected host has failed to respond

During handling of the above exception, another exception occurred:

Traceback (most recent call last):
  File "C:\anaconda3\envs\RLV\lib\site-packages\ray\reporter.py", line 234, in run
    self.perform_iteration()
  File "C:\anaconda3\envs\RLV\lib\site-packages\ray\reporter.py", line 219, in perform_iteration
    jsonify_asdict(stats),
  File "C:\anaconda3\envs\RLV\lib\site-packages\redis\client.py", line 3052, in publish
    return self.execute_command('PUBLISH', channel, message)
  File "C:\anaconda3\envs\RLV\lib\site-packages\redis\client.py", line 881, in execute_command
    conn = self.connection or pool.get_connection(command_name, **options)
  File "C:\anaconda3\envs\RLV\lib\site-packages\redis\connection.py", line 1178, in get_connection
    connection.connect()
  File "C:\anaconda3\envs\RLV\lib\site-packages\redis\connection.py", line 555, in connect
    raise ConnectionError(self._error_message(e))
redis.exceptions.ConnectionError: Error 10060 connecting to 10.16.234.175:6379. A connection attempt failed because the connected party did not properly respond after a period of time, or established connection failed because connected host has failed to respond.
Traceback (most recent call last):
  File "C:\anaconda3\envs\RLV\lib\site-packages\redis\connection.py", line 550, in connect
    sock = self._connect()
  File "C:\anaconda3\envs\RLV\lib\site-packages\redis\connection.py", line 607, in _connect
    raise err
  File "C:\anaconda3\envs\RLV\lib\site-packages\redis\connection.py", line 595, in _connect
    sock.connect(socket_address)
TimeoutError: [WinError 10060] A connection attempt failed because the connected party did not properly respond after a period of time, or established connection failed because connected host has failed to respond

During handling of the above exception, another exception occurred:

Traceback (most recent call last):
  File "C:\anaconda3\envs\RLV\lib\site-packages\ray\reporter.py", line 234, in run
    self.perform_iteration()
  File "C:\anaconda3\envs\RLV\lib\site-packages\ray\reporter.py", line 219, in perform_iteration
    jsonify_asdict(stats),
  File "C:\anaconda3\envs\RLV\lib\site-packages\redis\client.py", line 3052, in publish
    return self.execute_command('PUBLISH', channel, message)
  File "C:\anaconda3\envs\RLV\lib\site-packages\redis\client.py", line 881, in execute_command
    conn = self.connection or pool.get_connection(command_name, **options)
  File "C:\anaconda3\envs\RLV\lib\site-packages\redis\connection.py", line 1178, in get_connection
    connection.connect()
  File "C:\anaconda3\envs\RLV\lib\site-packages\redis\connection.py", line 555, in connect
    raise ConnectionError(self._error_message(e))
redis.exceptions.ConnectionError: Error 10060 connecting to 10.16.234.175:6379. A connection attempt failed because the connected party did not properly respond after a period of time, or established connection failed because connected host has failed to respond.
Traceback (most recent call last):
  File "C:\anaconda3\envs\RLV\lib\site-packages\redis\connection.py", line 550, in connect
    sock = self._connect()
  File "C:\anaconda3\envs\RLV\lib\site-packages\redis\connection.py", line 607, in _connect
    raise err
  File "C:\anaconda3\envs\RLV\lib\site-packages\redis\connection.py", line 595, in _connect
    sock.connect(socket_address)
TimeoutError: [WinError 10060] A connection attempt failed because the connected party did not properly respond after a period of time, or established connection failed because connected host has failed to respond

During handling of the above exception, another exception occurred:

Traceback (most recent call last):
  File "C:\anaconda3\envs\RLV\lib\site-packages\ray\reporter.py", line 234, in run
    self.perform_iteration()
  File "C:\anaconda3\envs\RLV\lib\site-packages\ray\reporter.py", line 219, in perform_iteration
    jsonify_asdict(stats),
  File "C:\anaconda3\envs\RLV\lib\site-packages\redis\client.py", line 3052, in publish
    return self.execute_command('PUBLISH', channel, message)
  File "C:\anaconda3\envs\RLV\lib\site-packages\redis\client.py", line 881, in execute_command
    conn = self.connection or pool.get_connection(command_name, **options)
  File "C:\anaconda3\envs\RLV\lib\site-packages\redis\connection.py", line 1178, in get_connection
    connection.connect()
  File "C:\anaconda3\envs\RLV\lib\site-packages\redis\connection.py", line 555, in connect
    raise ConnectionError(self._error_message(e))
redis.exceptions.ConnectionError: Error 10060 connecting to 10.16.234.175:6379. A connection attempt failed because the connected party did not properly respond after a period of time, or established connection failed because connected host has failed to respond.
Traceback (most recent call last):
  File "C:\anaconda3\envs\RLV\lib\site-packages\redis\connection.py", line 550, in connect
    sock = self._connect()
  File "C:\anaconda3\envs\RLV\lib\site-packages\redis\connection.py", line 607, in _connect
    raise err
  File "C:\anaconda3\envs\RLV\lib\site-packages\redis\connection.py", line 595, in _connect
    sock.connect(socket_address)
TimeoutError: [WinError 10060] A connection attempt failed because the connected party did not properly respond after a period of time, or established connection failed because connected host has failed to respond

During handling of the above exception, another exception occurred:

Traceback (most recent call last):
  File "C:\anaconda3\envs\RLV\lib\site-packages\ray\reporter.py", line 234, in run
    self.perform_iteration()
  File "C:\anaconda3\envs\RLV\lib\site-packages\ray\reporter.py", line 219, in perform_iteration
    jsonify_asdict(stats),
  File "C:\anaconda3\envs\RLV\lib\site-packages\redis\client.py", line 3052, in publish
    return self.execute_command('PUBLISH', channel, message)
  File "C:\anaconda3\envs\RLV\lib\site-packages\redis\client.py", line 881, in execute_command
    conn = self.connection or pool.get_connection(command_name, **options)
  File "C:\anaconda3\envs\RLV\lib\site-packages\redis\connection.py", line 1178, in get_connection
    connection.connect()
  File "C:\anaconda3\envs\RLV\lib\site-packages\redis\connection.py", line 555, in connect
    raise ConnectionError(self._error_message(e))
redis.exceptions.ConnectionError: Error 10060 connecting to 10.16.234.175:6379. A connection attempt failed because the connected party did not properly respond after a period of time, or established connection failed because connected host has failed to respond.
Traceback (most recent call last):
  File "C:\anaconda3\envs\RLV\lib\site-packages\redis\connection.py", line 550, in connect
    sock = self._connect()
  File "C:\anaconda3\envs\RLV\lib\site-packages\redis\connection.py", line 607, in _connect
    raise err
  File "C:\anaconda3\envs\RLV\lib\site-packages\redis\connection.py", line 595, in _connect
    sock.connect(socket_address)
TimeoutError: [WinError 10060] A connection attempt failed because the connected party did not properly respond after a period of time, or established connection failed because connected host has failed to respond

During handling of the above exception, another exception occurred:

Traceback (most recent call last):
  File "C:\anaconda3\envs\RLV\lib\site-packages\ray\reporter.py", line 234, in run
    self.perform_iteration()
  File "C:\anaconda3\envs\RLV\lib\site-packages\ray\reporter.py", line 219, in perform_iteration
    jsonify_asdict(stats),
  File "C:\anaconda3\envs\RLV\lib\site-packages\redis\client.py", line 3052, in publish
    return self.execute_command('PUBLISH', channel, message)
  File "C:\anaconda3\envs\RLV\lib\site-packages\redis\client.py", line 881, in execute_command
    conn = self.connection or pool.get_connection(command_name, **options)
  File "C:\anaconda3\envs\RLV\lib\site-packages\redis\connection.py", line 1178, in get_connection
    connection.connect()
  File "C:\anaconda3\envs\RLV\lib\site-packages\redis\connection.py", line 555, in connect
    raise ConnectionError(self._error_message(e))
redis.exceptions.ConnectionError: Error 10060 connecting to 10.16.234.175:6379. A connection attempt failed because the connected party did not properly respond after a period of time, or established connection failed because connected host has failed to respond.
